Workbook

Sheet Audit Checklist
A1: Clinical Documentation Audit
A2: One chart per sheet · tick each item · scoring & rating are automatic
A4: Provider: | C4: Date of Service: | E4: How to audit a claim 1. Click a Claim 01–10 tab (bottom of the workbook) 2. Fill yellow header + ratings — auto-scores 3. Move to the next Claim tab · repeat Global metrics roll up automatically • Open the Provider Metrics tab — it pulls the 10 claim scores live from the Claim tabs so you see the running provider average. Start a new provider (after 10 claims) 1. Ctrl+click Claim 01 through Claim 10 to group them 2. Select the yellow header + rating + note cells on any tab 3. Press Delete → all 10 tabs clear at once 4. Right-click any tab → Ungroup Sheets
A5: Claim Number: | C5: Auditor:
A6: Category: | C6: Payer:
A7: Date of audit:
A8: § | B8: Documentation element | C8: Rating | D8: Pts | E8: Notes / evidence
A9: A · Diagnosis Accuracy (4 items)
A10: A1 | B10: All reported diagnoses are clinically supported in the note | D10: =IF(C10="✓ Met",1,IF(C10="△ Partial",0.5,IF(C10="✗ Not Met",0,IF(C10="N/A","",""))))
A11: A2 | B11: Chronic conditions actively addressed at this visit (not just carried forward) | D11: =IF(C11="✓ Met",1,IF(C11="△ Partial",0.5,IF(C11="✗ Not Met",0,IF(C11="N/A","",""))))
A12: A3 | B12: No unsupported or resolved conditions billed as active | D12: =IF(C12="✓ Met",1,IF(C12="△ Partial",0.5,IF(C12="✗ Not Met",0,IF(C12="N/A","",""))))
A13: A4 | B13: Problem list matches today's assessment & plan | D13: =IF(C13="✓ Met",1,IF(C13="△ Partial",0.5,IF(C13="✗ Not Met",0,IF(C13="N/A","",""))))
A15: B · Documentation Specificity (4 items)
A16: B1 | B16: ICD-10 codes at highest available specificity (avoid 'unspecified') | D16: =IF(C16="✓ Met",1,IF(C16="△ Partial",0.5,IF(C16="✗ Not Met",0,IF(C16="N/A","",""))))
A17: B2 | B17: Diabetes: type + complications + control specified | D17: =IF(C17="✓ Met",1,IF(C17="△ Partial",0.5,IF(C17="✗ Not Met",0,IF(C17="N/A","",""))))
A18: B3 | B18: S / O / A / P sections tell one consistent clinical story | D18: =IF(C18="✓ Met",1,IF(C18="△ Partial",0.5,IF(C18="✗ Not Met",0,IF(C18="N/A","",""))))
A19: B4 | B19: Note signed, dated, and closed by the rendering provider | D19: =IF(C19="✓ Met",1,IF(C19="△ Partial",0.5,IF(C19="✗ Not Met",0,IF(C19="N/A","",""))))
A21: C · SOAP Note Structure (4 items)
A22: C1 | B22: Subjective — patient's history, symptoms, and concerns clearly documented | D22: =IF(C22="✓ Met",1,IF(C22="△ Partial",0.5,IF(C22="✗ Not Met",0,IF(C22="N/A","",""))))
A23: C2 | B23: Objective — exam findings, vitals, and relevant test results documented | D23: =IF(C23="✓ Met",1,IF(C23="△ Partial",0.5,IF(C23="✗ Not Met",0,IF(C23="N/A","",""))))
A24: C3 | B24: Assessment — each diagnosis explicitly assessed with clinical reasoning | D24: =IF(C24="✓ Met",1,IF(C24="△ Partial",0.5,IF(C24="✗ Not Met",0,IF(C24="N/A","",""))))
A25: C4 | B25: Plan — treatment plan documented (medication / referral / testing / follow-up) | D25: =IF(C25="✓ Met",1,IF(C25="△ Partial",0.5,IF(C25="✗ Not Met",0,IF(C25="N/A","",""))))
A27: D · HCC Capture (2 items)
A28: D1 | B28: Prior-year HCCs recaptured (or explicitly resolved with rationale) | D28: =IF(C28="✓ Met",1,IF(C28="△ Partial",0.5,IF(C28="✗ Not Met",0,IF(C28="N/A","",""))))
A29: D2 | B29: Suspected undocumented chronic conditions captured with support | D29: =IF(C29="✓ Met",1,IF(C29="△ Partial",0.5,IF(C29="✗ Not Met",0,IF(C29="N/A","",""))))
A31: E · Documentation Supporting Quality Measures (2 items)
A32: E1 | B32: Screening / measure results documented with specific values (PHQ-9, GAD-7, BMI, BP, HbA1c) — not just 'screened' or 'normal' | D32: =IF(C32="✓ Met",1,IF(C32="△ Partial",0.5,IF(C32="✗ Not Met",0,IF(C32="N/A","",""))))
A33: E2 | B33: Follow-up plan documented when a screening is positive or a result is abnormal (positive PHQ-9 → depression plan; elevated BMI → nutrition counseling) | D33: =IF(C33="✓ Met",1,IF(C33="△ Partial",0.5,IF(C33="✗ Not Met",0,IF(C33="N/A","",""))))
A36: SUMMARY
A37: § | B37: Category | C37: Applicable | D37: % Met
A38: A | B38: Diagnosis Accuracy | C38: =COUNTIF(C10:C13,"✓ Met")+COUNTIF(C10:C13,"△ Partial")+COUNTIF(C10:C13,"✗ Not Met") | D38: =IFERROR(SUM(D10:D13)/C38,"")
A39: B | B39: Documentation Specificity | C39: =COUNTIF(C16:C19,"✓ Met")+COUNTIF(C16:C19,"△ Partial")+COUNTIF(C16:C19,"✗ Not Met") | D39: =IFERROR(SUM(D16:D19)/C39,"")
A40: C | B40: SOAP Note Structure | C40: =COUNTIF(C22:C25,"✓ Met")+COUNTIF(C22:C25,"△ Partial")+COUNTIF(C22:C25,"✗ Not Met") | D40: =IFERROR(SUM(D22:D25)/C40,"")
A41: D | B41: HCC Capture | C41: =COUNTIF(C28:C29,"✓ Met")+COUNTIF(C28:C29,"△ Partial")+COUNTIF(C28:C29,"✗ Not Met") | D41: =IFERROR(SUM(D28:D29)/C41,"")
A42: E | B42: Documentation Supporting Quality Measures | C42: =COUNTIF(C32:C33,"✓ Met")+COUNTIF(C32:C33,"△ Partial")+COUNTIF(C32:C33,"✗ Not Met") | D42: =IFERROR(SUM(D32:D33)/C42,"")
A44: OVERALL COMPLIANCE | D44: =IFERROR(SUMPRODUCT(D38:D42,C38:C42)/SUM(C38:C42),"")
A45: PERFORMANCE BAND | D45: =IF(D44="","",IF(D44>=0.95,"Excellent",IF(D44>=0.90,"Meets Expectations",IF(D44>=0.80,"Needs Improvement","Corrective Education Required"))))

Sheet Provider Metrics
A1: Provider Metrics — Rollup Across the 10 Claim Tabs
A2: Live rollup of the current provider's 10 claims. As you fill each Claim tab, this tab shows the running provider average, distribution across bands, and overall Performance Band.
B4: Provider (from Claim 01) | D4: ='Claim 01'!B4
A6: Claims completed | D6: Average compliance %
A7: =COUNT('Claim 01:Claim 10'!D44) | D7: =IFERROR(AVERAGE('Claim 01:Claim 10'!D44),"")
A10: Meeting Expectations (≥90%) | D10: Corrective Required (<80%)
A11: =COUNTIFS(E17:E26,">=0.9",E17:E26,"<>") | D11: =COUNTIFS(E17:E26,"<0.8",E17:E26,">0")
A15: Per-Claim Breakdown
A16: # | B16: Provider | C16: Claim # | D16: DOS | E16: Compliance % | F16: Rating
A17: 1 | B17: ='Claim 01'!B4 | C17: ='Claim 01'!B5 | D17: ='Claim 01'!D4 | E17: =IFERROR('Claim 01'!D44,"") | F17: =IFERROR('Claim 01'!D45,"")
A18: 2 | B18: ='Claim 02'!B4 | C18: ='Claim 02'!B5 | D18: ='Claim 02'!D4 | E18: =IFERROR('Claim 02'!D44,"") | F18: =IFERROR('Claim 02'!D45,"")
A19: 3 | B19: ='Claim 03'!B4 | C19: ='Claim 03'!B5 | D19: ='Claim 03'!D4 | E19: =IFERROR('Claim 03'!D44,"") | F19: =IFERROR('Claim 03'!D45,"")
A20: 4 | B20: ='Claim 04'!B4 | C20: ='Claim 04'!B5 | D20: ='Claim 04'!D4 | E20: =IFERROR('Claim 04'!D44,"") | F20: =IFERROR('Claim 04'!D45,"")
A21: 5 | B21: ='Claim 05'!B4 | C21: ='Claim 05'!B5 | D21: ='Claim 05'!D4 | E21: =IFERROR('Claim 05'!D44,"") | F21: =IFERROR('Claim 05'!D45,"")
A22: 6 | B22: ='Claim 06'!B4 | C22: ='Claim 06'!B5 | D22: ='Claim 06'!D4 | E22: =IFERROR('Claim 06'!D44,"") | F22: =IFERROR('Claim 06'!D45,"")
A23: 7 | B23: ='Claim 07'!B4 | C23: ='Claim 07'!B5 | D23: ='Claim 07'!D4 | E23: =IFERROR('Claim 07'!D44,"") | F23: =IFERROR('Claim 07'!D45,"")
A24: 8 | B24: ='Claim 08'!B4 | C24: ='Claim 08'!B5 | D24: ='Claim 08'!D4 | E24: =IFERROR('Claim 08'!D44,"") | F24: =IFERROR('Claim 08'!D45,"")
A25: 9 | B25: ='Claim 09'!B4 | C25: ='Claim 09'!B5 | D25: ='Claim 09'!D4 | E25: =IFERROR('Claim 09'!D44,"") | F25: =IFERROR('Claim 09'!D45,"")
A26: 10 | B26: ='Claim 10'!B4 | C26: ='Claim 10'!B5 | D26: ='Claim 10'!D4 | E26: =IFERROR('Claim 10'!D44,"") | F26: =IFERROR('Claim 10'!D45,"")
A28: OVERALL PROVIDER PERFORMANCE BAND | E28: =IF(D7="","",IF(D7>=0.95,"Excellent",IF(D7>=0.9,"Meets Expectations",IF(D7>=0.8,"Needs Improvement","Corrective Education Required"))))
A30: Band Distribution (10 claims)
A31: Band | F31: Count
A32: Excellent | F32: =COUNTIF(F17:F26,"Excellent")
A33: Meets Expectations | F33: =COUNTIF(F17:F26,"Meets Expectations")
A34: Needs Improvement | F34: =COUNTIF(F17:F26,"Needs Improvement")
A35: Corrective Education Required | F35: =COUNTIF(F17:F26,"Corrective Education Required")

Sheet Claim 01
A1: Clinical Documentation Audit
A2: One chart per sheet · tick each item · scoring & rating are automatic
A4: Provider: | C4: Date of Service: | E4: How to audit a claim 1. Click a Claim 01–10 tab (bottom of the workbook) 2. Fill yellow header + ratings — auto-scores 3. Move to the next Claim tab · repeat Global metrics roll up automatically • Open the Provider Metrics tab — it pulls the 10 claim scores live from the Claim tabs so you see the running provider average. Start a new provider (after 10 claims) 1. Ctrl+click Claim 01 through Claim 10 to group them 2. Select the yellow header + rating + note cells on any tab 3. Press Delete → all 10 tabs clear at once 4. Right-click any tab → Ungroup Sheets
A5: Claim Number: | C5: Auditor:
A6: Category: | C6: Payer:
A7: Date of audit:
A8: § | B8: Documentation element | D8: Pts
A9: A · Diagnosis Accuracy (4 items)
A10: A1 | B10: All reported diagnoses are clinically supported in the note | D10: =IF(C10="✓ Met",1,IF(C10="△ Partial",0.5,IF(C10="✗ Not Met",0,IF(C10="N/A","",""))))
A11: A2 | B11: Chronic conditions actively addressed at this visit (not just carried forward) | D11: =IF(C11="✓ Met",1,IF(C11="△ Partial",0.5,IF(C11="✗ Not Met",0,IF(C11="N/A","",""))))
A12: A3 | B12: No unsupported or resolved conditions billed as active | D12: =IF(C12="✓ Met",1,IF(C12="△ Partial",0.5,IF(C12="✗ Not Met",0,IF(C12="N/A","",""))))
A13: A4 | B13: Problem list matches today's assessment & plan | D13: =IF(C13="✓ Met",1,IF(C13="△ Partial",0.5,IF(C13="✗ Not Met",0,IF(C13="N/A","",""))))
A15: B · Documentation Specificity (4 items)
A16: B1 | B16: ICD-10 codes at highest available specificity (avoid 'unspecified') | D16: =IF(C16="✓ Met",1,IF(C16="△ Partial",0.5,IF(C16="✗ Not Met",0,IF(C16="N/A","",""))))
A17: B2 | B17: Diabetes: type + complications + control specified | D17: =IF(C17="✓ Met",1,IF(C17="△ Partial",0.5,IF(C17="✗ Not Met",0,IF(C17="N/A","",""))))
A18: B3 | B18: S / O / A / P sections tell one consistent clinical story | D18: =IF(C18="✓ Met",1,IF(C18="△ Partial",0.5,IF(C18="✗ Not Met",0,IF(C18="N/A","",""))))
A19: B4 | B19: Note signed, dated, and closed by the rendering provider | D19: =IF(C19="✓ Met",1,IF(C19="△ Partial",0.5,IF(C19="✗ Not Met",0,IF(C19="N/A","",""))))
A21: C · SOAP Note Structure (4 items)
A22: C1 | B22: Subjective — patient's history, symptoms, and concerns clearly documented | D22: =IF(C22="✓ Met",1,IF(C22="△ Partial",0.5,IF(C22="✗ Not Met",0,IF(C22="N/A","",""))))
A23: C2 | B23: Objective — exam findings, vitals, and relevant test results documented | D23: =IF(C23="✓ Met",1,IF(C23="△ Partial",0.5,IF(C23="✗ Not Met",0,IF(C23="N/A","",""))))
A24: C3 | B24: Assessment — each diagnosis explicitly assessed with clinical reasoning | D24: =IF(C24="✓ Met",1,IF(C24="△ Partial",0.5,IF(C24="✗ Not Met",0,IF(C24="N/A","",""))))
A25: C4 | B25: Plan — treatment plan documented (medication / referral / testing / follow-up) | D25: =IF(C25="✓ Met",1,IF(C25="△ Partial",0.5,IF(C25="✗ Not Met",0,IF(C25="N/A","",""))))
A27: D · HCC Capture (2 items)
A28: D1 | B28: Prior-year HCCs recaptured (or explicitly resolved with rationale) | D28: =IF(C28="✓ Met",1,IF(C28="△ Partial",0.5,IF(C28="✗ Not Met",0,IF(C28="N/A","",""))))
A29: D2 | B29: Suspected undocumented chronic conditions captured with support | D29: =IF(C29="✓ Met",1,IF(C29="△ Partial",0.5,IF(C29="✗ Not Met",0,IF(C29="N/A","",""))))
A31: E · Documentation Supporting Quality Measures (2 items)
A32: E1 | B32: Screening / measure results documented with specific values (PHQ-9, GAD-7, BMI, BP, HbA1c) — not just 'screened' or 'normal' | D32: =IF(C32="✓ Met",1,IF(C32="△ Partial",0.5,IF(C32="✗ Not Met",0,IF(C32="N/A","",""))))
A33: E2 | B33: Follow-up plan documented when a screening is positive or a result is abnormal (positive PHQ-9 → depression plan; elevated BMI → nutrition counseling) | D33: =IF(C33="✓ Met",1,IF(C33="△ Partial",0.5,IF(C33="✗ Not Met",0,IF(C33="N/A","",""))))
A36: SUMMARY
A37: § | B37: Category | D37: % Met
A38: A | B38: Diagnosis Accuracy | C38: =COUNTIF(C10:C13,"✓ Met")+COUNTIF(C10:C13,"△ Partial")+COUNTIF(C10:C13,"✗ Not Met") | D38: =IFERROR(SUM(D10:D13)/C38,"")
A39: B | B39: Documentation Specificity | C39: =COUNTIF(C16:C19,"✓ Met")+COUNTIF(C16:C19,"△ Partial")+COUNTIF(C16:C19,"✗ Not Met") | D39: =IFERROR(SUM(D16:D19)/C39,"")
A40: C | B40: SOAP Note Structure | C40: =COUNTIF(C22:C25,"✓ Met")+COUNTIF(C22:C25,"△ Partial")+COUNTIF(C22:C25,"✗ Not Met") | D40: =IFERROR(SUM(D22:D25)/C40,"")
A41: D | B41: HCC Capture | C41: =COUNTIF(C28:C29,"✓ Met")+COUNTIF(C28:C29,"△ Partial")+COUNTIF(C28:C29,"✗ Not Met") | D41: =IFERROR(SUM(D28:D29)/C41,"")
A42: E | B42: Documentation Supporting Quality Measures | C42: =COUNTIF(C32:C33,"✓ Met")+COUNTIF(C32:C33,"△ Partial")+COUNTIF(C32:C33,"✗ Not Met") | D42: =IFERROR(SUM(D32:D33)/C42,"")
A44: OVERALL COMPLIANCE | D44: =IFERROR(SUMPRODUCT(D38:D42,C38:C42)/SUM(C38:C42),"")
A45: PERFORMANCE BAND | D45: =IF(D44="","",IF(D44>=0.95,"Excellent",IF(D44>=0.90,"Meets Expectations",IF(D44>=0.80,"Needs Improvement","Corrective Education Required"))))

Sheet Claim 02
A1: Clinical Documentation Audit
A2: One chart per sheet · tick each item · scoring & rating are automatic
A4: Provider: | C4: Date of Service: | E4: How to audit a claim 1. Click a Claim 01–10 tab (bottom of the workbook) 2. Fill yellow header + ratings — auto-scores 3. Move to the next Claim tab · repeat Global metrics roll up automatically • Open the Provider Metrics tab — it pulls the 10 claim scores live from the Claim tabs so you see the running provider average. Start a new provider (after 10 claims) 1. Ctrl+click Claim 01 through Claim 10 to group them 2. Select the yellow header + rating + note cells on any tab 3. Press Delete → all 10 tabs clear at once 4. Right-click any tab → Ungroup Sheets
A5: Claim Number: | C5: Auditor:
A6: Category: | C6: Payer:
A7: Date of audit:
A8: § | B8: Documentation element | D8: Pts
A9: A · Diagnosis Accuracy (4 items)
A10: A1 | B10: All reported diagnoses are clinically supported in the note | D10: =IF(C10="✓ Met",1,IF(C10="△ Partial",0.5,IF(C10="✗ Not Met",0,IF(C10="N/A","",""))))
A11: A2 | B11: Chronic conditions actively addressed at this visit (not just carried forward) | D11: =IF(C11="✓ Met",1,IF(C11="△ Partial",0.5,IF(C11="✗ Not Met",0,IF(C11="N/A","",""))))
A12: A3 | B12: No unsupported or resolved conditions billed as active | D12: =IF(C12="✓ Met",1,IF(C12="△ Partial",0.5,IF(C12="✗ Not Met",0,IF(C12="N/A","",""))))
A13: A4 | B13: Problem list matches today's assessment & plan | D13: =IF(C13="✓ Met",1,IF(C13="△ Partial",0.5,IF(C13="✗ Not Met",0,IF(C13="N/A","",""))))
A15: B · Documentation Specificity (4 items)
A16: B1 | B16: ICD-10 codes at highest available specificity (avoid 'unspecified') | D16: =IF(C16="✓ Met",1,IF(C16="△ Partial",0.5,IF(C16="✗ Not Met",0,IF(C16="N/A","",""))))
A17: B2 | B17: Diabetes: type + complications + control specified | D17: =IF(C17="✓ Met",1,IF(C17="△ Partial",0.5,IF(C17="✗ Not Met",0,IF(C17="N/A","",""))))
A18: B3 | B18: S / O / A / P sections tell one consistent clinical story | D18: =IF(C18="✓ Met",1,IF(C18="△ Partial",0.5,IF(C18="✗ Not Met",0,IF(C18="N/A","",""))))
A19: B4 | B19: Note signed, dated, and closed by the rendering provider | D19: =IF(C19="✓ Met",1,IF(C19="△ Partial",0.5,IF(C19="✗ Not Met",0,IF(C19="N/A","",""))))
A21: C · SOAP Note Structure (4 items)
A22: C1 | B22: Subjective — patient's history, symptoms, and concerns clearly documented | D22: =IF(C22="✓ Met",1,IF(C22="△ Partial",0.5,IF(C22="✗ Not Met",0,IF(C22="N/A","",""))))
A23: C2 | B23: Objective — exam findings, vitals, and relevant test results documented | D23: =IF(C23="✓ Met",1,IF(C23="△ Partial",0.5,IF(C23="✗ Not Met",0,IF(C23="N/A","",""))))
A24: C3 | B24: Assessment — each diagnosis explicitly assessed with clinical reasoning | D24: =IF(C24="✓ Met",1,IF(C24="△ Partial",0.5,IF(C24="✗ Not Met",0,IF(C24="N/A","",""))))
A25: C4 | B25: Plan — treatment plan documented (medication / referral / testing / follow-up) | D25: =IF(C25="✓ Met",1,IF(C25="△ Partial",0.5,IF(C25="✗ Not Met",0,IF(C25="N/A","",""))))
A27: D · HCC Capture (2 items)
A28: D1 | B28: Prior-year HCCs recaptured (or explicitly resolved with rationale) | D28: =IF(C28="✓ Met",1,IF(C28="△ Partial",0.5,IF(C28="✗ Not Met",0,IF(C28="N/A","",""))))
A29: D2 | B29: Suspected undocumented chronic conditions captured with support | D29: =IF(C29="✓ Met",1,IF(C29="△ Partial",0.5,IF(C29="✗ Not Met",0,IF(C29="N/A","",""))))
A31: E · Documentation Supporting Quality Measures (2 items)
A32: E1 | B32: Screening / measure results documented with specific values (PHQ-9, GAD-7, BMI, BP, HbA1c) — not just 'screened' or 'normal' | D32: =IF(C32="✓ Met",1,IF(C32="△ Partial",0.5,IF(C32="✗ Not Met",0,IF(C32="N/A","",""))))
A33: E2 | B33: Follow-up plan documented when a screening is positive or a result is abnormal (positive PHQ-9 → depression plan; elevated BMI → nutrition counseling) | D33: =IF(C33="✓ Met",1,IF(C33="△ Partial",0.5,IF(C33="✗ Not Met",0,IF(C33="N/A","",""))))
A36: SUMMARY
A37: § | B37: Category | D37: % Met
A38: A | B38: Diagnosis Accuracy | C38: =COUNTIF(C10:C13,"✓ Met")+COUNTIF(C10:C13,"△ Partial")+COUNTIF(C10:C13,"✗ Not Met") | D38: =IFERROR(SUM(D10:D13)/C38,"")
A39: B | B39: Documentation Specificity | C39: =COUNTIF(C16:C19,"✓ Met")+COUNTIF(C16:C19,"△ Partial")+COUNTIF(C16:C19,"✗ Not Met") | D39: =IFERROR(SUM(D16:D19)/C39,"")
A40: C | B40: SOAP Note Structure | C40: =COUNTIF(C22:C25,"✓ Met")+COUNTIF(C22:C25,"△ Partial")+COUNTIF(C22:C25,"✗ Not Met") | D40: =IFERROR(SUM(D22:D25)/C40,"")
A41: D | B41: HCC Capture | C41: =COUNTIF(C28:C29,"✓ Met")+COUNTIF(C28:C29,"△ Partial")+COUNTIF(C28:C29,"✗ Not Met") | D41: =IFERROR(SUM(D28:D29)/C41,"")
A42: E | B42: Documentation Supporting Quality Measures | C42: =COUNTIF(C32:C33,"✓ Met")+COUNTIF(C32:C33,"△ Partial")+COUNTIF(C32:C33,"✗ Not Met") | D42: =IFERROR(SUM(D32:D33)/C42,"")
A44: OVERALL COMPLIANCE | D44: =IFERROR(SUMPRODUCT(D38:D42,C38:C42)/SUM(C38:C42),"")
A45: PERFORMANCE BAND | D45: =IF(D44="","",IF(D44>=0.95,"Excellent",IF(D44>=0.90,"Meets Expectations",IF(D44>=0.80,"Needs Improvement","Corrective Education Required"))))

Sheet Claim 03
A1: Clinical Documentation Audit
A2: One chart per sheet · tick each item · scoring & rating are automatic
A4: Provider: | C4: Date of Service: | E4: How to audit a claim 1. Click a Claim 01–10 tab (bottom of the workbook) 2. Fill yellow header + ratings — auto-scores 3. Move to the next Claim tab · repeat Global metrics roll up automatically • Open the Provider Metrics tab — it pulls the 10 claim scores live from the Claim tabs so you see the running provider average. Start a new provider (after 10 claims) 1. Ctrl+click Claim 01 through Claim 10 to group them 2. Select the yellow header + rating + note cells on any tab 3. Press Delete → all 10 tabs clear at once 4. Right-click any tab → Ungroup Sheets
A5: Claim Number: | C5: Auditor:
A6: Category: | C6: Payer:
A7: Date of audit:
A8: § | B8: Documentation element | D8: Pts
A9: A · Diagnosis Accuracy (4 items)
A10: A1 | B10: All reported diagnoses are clinically supported in the note | D10: =IF(C10="✓ Met",1,IF(C10="△ Partial",0.5,IF(C10="✗ Not Met",0,IF(C10="N/A","",""))))
A11: A2 | B11: Chronic conditions actively addressed at this visit (not just carried forward) | D11: =IF(C11="✓ Met",1,IF(C11="△ Partial",0.5,IF(C11="✗ Not Met",0,IF(C11="N/A","",""))))
A12: A3 | B12: No unsupported or resolved conditions billed as active | D12: =IF(C12="✓ Met",1,IF(C12="△ Partial",0.5,IF(C12="✗ Not Met",0,IF(C12="N/A","",""))))
A13: A4 | B13: Problem list matches today's assessment & plan | D13: =IF(C13="✓ Met",1,IF(C13="△ Partial",0.5,IF(C13="✗ Not Met",0,IF(C13="N/A","",""))))
A15: B · Documentation Specificity (4 items)
A16: B1 | B16: ICD-10 codes at highest available specificity (avoid 'unspecified') | D16: =IF(C16="✓ Met",1,IF(C16="△ Partial",0.5,IF(C16="✗ Not Met",0,IF(C16="N/A","",""))))
A17: B2 | B17: Diabetes: type + complications + control specified | D17: =IF(C17="✓ Met",1,IF(C17="△ Partial",0.5,IF(C17="✗ Not Met",0,IF(C17="N/A","",""))))
A18: B3 | B18: S / O / A / P sections tell one consistent clinical story | D18: =IF(C18="✓ Met",1,IF(C18="△ Partial",0.5,IF(C18="✗ Not Met",0,IF(C18="N/A","",""))))
A19: B4 | B19: Note signed, dated, and closed by the rendering provider | D19: =IF(C19="✓ Met",1,IF(C19="△ Partial",0.5,IF(C19="✗ Not Met",0,IF(C19="N/A","",""))))
A21: C · SOAP Note Structure (4 items)
A22: C1 | B22: Subjective — patient's history, symptoms, and concerns clearly documented | D22: =IF(C22="✓ Met",1,IF(C22="△ Partial",0.5,IF(C22="✗ Not Met",0,IF(C22="N/A","",""))))
A23: C2 | B23: Objective — exam findings, vitals, and relevant test results documented | D23: =IF(C23="✓ Met",1,IF(C23="△ Partial",0.5,IF(C23="✗ Not Met",0,IF(C23="N/A","",""))))
A24: C3 | B24: Assessment — each diagnosis explicitly assessed with clinical reasoning | D24: =IF(C24="✓ Met",1,IF(C24="△ Partial",0.5,IF(C24="✗ Not Met",0,IF(C24="N/A","",""))))
A25: C4 | B25: Plan — treatment plan documented (medication / referral / testing / follow-up) | D25: =IF(C25="✓ Met",1,IF(C25="△ Partial",0.5,IF(C25="✗ Not Met",0,IF(C25="N/A","",""))))
A27: D · HCC Capture (2 items)
A28: D1 | B28: Prior-year HCCs recaptured (or explicitly resolved with rationale) | D28: =IF(C28="✓ Met",1,IF(C28="△ Partial",0.5,IF(C28="✗ Not Met",0,IF(C28="N/A","",""))))
A29: D2 | B29: Suspected undocumented chronic conditions captured with support | D29: =IF(C29="✓ Met",1,IF(C29="△ Partial",0.5,IF(C29="✗ Not Met",0,IF(C29="N/A","",""))))
A31: E · Documentation Supporting Quality Measures (2 items)
A32: E1 | B32: Screening / measure results documented with specific values (PHQ-9, GAD-7, BMI, BP, HbA1c) — not just 'screened' or 'normal' | D32: =IF(C32="✓ Met",1,IF(C32="△ Partial",0.5,IF(C32="✗ Not Met",0,IF(C32="N/A","",""))))
A33: E2 | B33: Follow-up plan documented when a screening is positive or a result is abnormal (positive PHQ-9 → depression plan; elevated BMI → nutrition counseling) | D33: =IF(C33="✓ Met",1,IF(C33="△ Partial",0.5,IF(C33="✗ Not Met",0,IF(C33="N/A","",""))))
A36: SUMMARY
A37: § | B37: Category | D37: % Met
A38: A | B38: Diagnosis Accuracy | C38: =COUNTIF(C10:C13,"✓ Met")+COUNTIF(C10:C13,"△ Partial")+COUNTIF(C10:C13,"✗ Not Met") | D38: =IFERROR(SUM(D10:D13)/C38,"")
A39: B | B39: Documentation Specificity | C39: =COUNTIF(C16:C19,"✓ Met")+COUNTIF(C16:C19,"△ Partial")+COUNTIF(C16:C19,"✗ Not Met") | D39: =IFERROR(SUM(D16:D19)/C39,"")
A40: C | B40: SOAP Note Structure | C40: =COUNTIF(C22:C25,"✓ Met")+COUNTIF(C22:C25,"△ Partial")+COUNTIF(C22:C25,"✗ Not Met") | D40: =IFERROR(SUM(D22:D25)/C40,"")
A41: D | B41: HCC Capture | C41: =COUNTIF(C28:C29,"✓ Met")+COUNTIF(C28:C29,"△ Partial")+COUNTIF(C28:C29,"✗ Not Met") | D41: =IFERROR(SUM(D28:D29)/C41,"")
A42: E | B42: Documentation Supporting Quality Measures | C42: =COUNTIF(C32:C33,"✓ Met")+COUNTIF(C32:C33,"△ Partial")+COUNTIF(C32:C33,"✗ Not Met") | D42: =IFERROR(SUM(D32:D33)/C42,"")
A44: OVERALL COMPLIANCE | D44: =IFERROR(SUMPRODUCT(D38:D42,C38:C42)/SUM(C38:C42),"")
A45: PERFORMANCE BAND | D45: =IF(D44="","",IF(D44>=0.95,"Excellent",IF(D44>=0.90,"Meets Expectations",IF(D44>=0.80,"Needs Improvement","Corrective Education Required"))))

Sheet Claim 04
A1: Clinical Documentation Audit
A2: One chart per sheet · tick each item · scoring & rating are automatic
A4: Provider: | C4: Date of Service: | E4: How to audit a claim 1. Click a Claim 01–10 tab (bottom of the workbook) 2. Fill yellow header + ratings — auto-scores 3. Move to the next Claim tab · repeat Global metrics roll up automatically • Open the Provider Metrics tab — it pulls the 10 claim scores live from the Claim tabs so you see the running provider average. Start a new provider (after 10 claims) 1. Ctrl+click Claim 01 through Claim 10 to group them 2. Select the yellow header + rating + note cells on any tab 3. Press Delete → all 10 tabs clear at once 4. Right-click any tab → Ungroup Sheets
A5: Claim Number: | C5: Auditor:
A6: Category: | C6: Payer:
A7: Date of audit:
A8: § | B8: Documentation element | D8: Pts
A9: A · Diagnosis Accuracy (4 items)
A10: A1 | B10: All reported diagnoses are clinically supported in the note | D10: =IF(C10="✓ Met",1,IF(C10="△ Partial",0.5,IF(C10="✗ Not Met",0,IF(C10="N/A","",""))))
A11: A2 | B11: Chronic conditions actively addressed at this visit (not just carried forward) | D11: =IF(C11="✓ Met",1,IF(C11="△ Partial",0.5,IF(C11="✗ Not Met",0,IF(C11="N/A","",""))))
A12: A3 | B12: No unsupported or resolved conditions billed as active | D12: =IF(C12="✓ Met",1,IF(C12="△ Partial",0.5,IF(C12="✗ Not Met",0,IF(C12="N/A","",""))))
A13: A4 | B13: Problem list matches today's assessment & plan | D13: =IF(C13="✓ Met",1,IF(C13="△ Partial",0.5,IF(C13="✗ Not Met",0,IF(C13="N/A","",""))))
A15: B · Documentation Specificity (4 items)
A16: B1 | B16: ICD-10 codes at highest available specificity (avoid 'unspecified') | D16: =IF(C16="✓ Met",1,IF(C16="△ Partial",0.5,IF(C16="✗ Not Met",0,IF(C16="N/A","",""))))
A17: B2 | B17: Diabetes: type + complications + control specified | D17: =IF(C17="✓ Met",1,IF(C17="△ Partial",0.5,IF(C17="✗ Not Met",0,IF(C17="N/A","",""))))
A18: B3 | B18: S / O / A / P sections tell one consistent clinical story | D18: =IF(C18="✓ Met",1,IF(C18="△ Partial",0.5,IF(C18="✗ Not Met",0,IF(C18="N/A","",""))))
A19: B4 | B19: Note signed, dated, and closed by the rendering provider | D19: =IF(C19="✓ Met",1,IF(C19="△ Partial",0.5,IF(C19="✗ Not Met",0,IF(C19="N/A","",""))))
A21: C · SOAP Note Structure (4 items)
A22: C1 | B22: Subjective — patient's history, symptoms, and concerns clearly documented | D22: =IF(C22="✓ Met",1,IF(C22="△ Partial",0.5,IF(C22="✗ Not Met",0,IF(C22="N/A","",""))))
A23: C2 | B23: Objective — exam findings, vitals, and relevant test results documented | D23: =IF(C23="✓ Met",1,IF(C23="△ Partial",0.5,IF(C23="✗ Not Met",0,IF(C23="N/A","",""))))
A24: C3 | B24: Assessment — each diagnosis explicitly assessed with clinical reasoning | D24: =IF(C24="✓ Met",1,IF(C24="△ Partial",0.5,IF(C24="✗ Not Met",0,IF(C24="N/A","",""))))
A25: C4 | B25: Plan — treatment plan documented (medication / referral / testing / follow-up) | D25: =IF(C25="✓ Met",1,IF(C25="△ Partial",0.5,IF(C25="✗ Not Met",0,IF(C25="N/A","",""))))
A27: D · HCC Capture (2 items)
A28: D1 | B28: Prior-year HCCs recaptured (or explicitly resolved with rationale) | D28: =IF(C28="✓ Met",1,IF(C28="△ Partial",0.5,IF(C28="✗ Not Met",0,IF(C28="N/A","",""))))
A29: D2 | B29: Suspected undocumented chronic conditions captured with support | D29: =IF(C29="✓ Met",1,IF(C29="△ Partial",0.5,IF(C29="✗ Not Met",0,IF(C29="N/A","",""))))
A31: E · Documentation Supporting Quality Measures (2 items)
A32: E1 | B32: Screening / measure results documented with specific values (PHQ-9, GAD-7, BMI, BP, HbA1c) — not just 'screened' or 'normal' | D32: =IF(C32="✓ Met",1,IF(C32="△ Partial",0.5,IF(C32="✗ Not Met",0,IF(C32="N/A","",""))))
A33: E2 | B33: Follow-up plan documented when a screening is positive or a result is abnormal (positive PHQ-9 → depression plan; elevated BMI → nutrition counseling) | D33: =IF(C33="✓ Met",1,IF(C33="△ Partial",0.5,IF(C33="✗ Not Met",0,IF(C33="N/A","",""))))
A36: SUMMARY
A37: § | B37: Category | D37: % Met
A38: A | B38: Diagnosis Accuracy | C38: =COUNTIF(C10:C13,"✓ Met")+COUNTIF(C10:C13,"△ Partial")+COUNTIF(C10:C13,"✗ Not Met") | D38: =IFERROR(SUM(D10:D13)/C38,"")
A39: B | B39: Documentation Specificity | C39: =COUNTIF(C16:C19,"✓ Met")+COUNTIF(C16:C19,"△ Partial")+COUNTIF(C16:C19,"✗ Not Met") | D39: =IFERROR(SUM(D16:D19)/C39,"")
A40: C | B40: SOAP Note Structure | C40: =COUNTIF(C22:C25,"✓ Met")+COUNTIF(C22:C25,"△ Partial")+COUNTIF(C22:C25,"✗ Not Met") | D40: =IFERROR(SUM(D22:D25)/C40,"")
A41: D | B41: HCC Capture | C41: =COUNTIF(C28:C29,"✓ Met")+COUNTIF(C28:C29,"△ Partial")+COUNTIF(C28:C29,"✗ Not Met") | D41: =IFERROR(SUM(D28:D29)/C41,"")
A42: E | B42: Documentation Supporting Quality Measures | C42: =COUNTIF(C32:C33,"✓ Met")+COUNTIF(C32:C33,"△ Partial")+COUNTIF(C32:C33,"✗ Not Met") | D42: =IFERROR(SUM(D32:D33)/C42,"")
A44: OVERALL COMPLIANCE | D44: =IFERROR(SUMPRODUCT(D38:D42,C38:C42)/SUM(C38:C42),"")
A45: PERFORMANCE BAND | D45: =IF(D44="","",IF(D44>=0.95,"Excellent",IF(D44>=0.90,"Meets Expectations",IF(D44>=0.80,"Needs Improvement","Corrective Education Required"))))

Sheet Claim 05
A1: Clinical Documentation Audit
A2: One chart per sheet · tick each item · scoring & rating are automatic
A4: Provider: | C4: Date of Service: | E4: How to audit a claim 1. Click a Claim 01–10 tab (bottom of the workbook) 2. Fill yellow header + ratings — auto-scores 3. Move to the next Claim tab · repeat Global metrics roll up automatically • Open the Provider Metrics tab — it pulls the 10 claim scores live from the Claim tabs so you see the running provider average. Start a new provider (after 10 claims) 1. Ctrl+click Claim 01 through Claim 10 to group them 2. Select the yellow header + rating + note cells on any tab 3. Press Delete → all 10 tabs clear at once 4. Right-click any tab → Ungroup Sheets
A5: Claim Number: | C5: Auditor:
A6: Category: | C6: Payer:
A7: Date of audit:
A8: § | B8: Documentation element | D8: Pts
A9: A · Diagnosis Accuracy (4 items)
A10: A1 | B10: All reported diagnoses are clinically supported in the note | D10: =IF(C10="✓ Met",1,IF(C10="△ Partial",0.5,IF(C10="✗ Not Met",0,IF(C10="N/A","",""))))
A11: A2 | B11: Chronic conditions actively addressed at this visit (not just carried forward) | D11: =IF(C11="✓ Met",1,IF(C11="△ Partial",0.5,IF(C11="✗ Not Met",0,IF(C11="N/A","",""))))
A12: A3 | B12: No unsupported or resolved conditions billed as active | D12: =IF(C12="✓ Met",1,IF(C12="△ Partial",0.5,IF(C12="✗ Not Met",0,IF(C12="N/A","",""))))
A13: A4 | B13: Problem list matches today's assessment & plan | D13: =IF(C13="✓ Met",1,IF(C13="△ Partial",0.5,IF(C13="✗ Not Met",0,IF(C13="N/A","",""))))
A15: B · Documentation Specificity (4 items)
A16: B1 | B16: ICD-10 codes at highest available specificity (avoid 'unspecified') | D16: =IF(C16="✓ Met",1,IF(C16="△ Partial",0.5,IF(C16="✗ Not Met",0,IF(C16="N/A","",""))))
A17: B2 | B17: Diabetes: type + complications + control specified | D17: =IF(C17="✓ Met",1,IF(C17="△ Partial",0.5,IF(C17="✗ Not Met",0,IF(C17="N/A","",""))))
A18: B3 | B18: S / O / A / P sections tell one consistent clinical story | D18: =IF(C18="✓ Met",1,IF(C18="△ Partial",0.5,IF(C18="✗ Not Met",0,IF(C18="N/A","",""))))
A19: B4 | B19: Note signed, dated, and closed by the rendering provider | D19: =IF(C19="✓ Met",1,IF(C19="△ Partial",0.5,IF(C19="✗ Not Met",0,IF(C19="N/A","",""))))
A21: C · SOAP Note Structure (4 items)
A22: C1 | B22: Subjective — patient's history, symptoms, and concerns clearly documented | D22: =IF(C22="✓ Met",1,IF(C22="△ Partial",0.5,IF(C22="✗ Not Met",0,IF(C22="N/A","",""))))
A23: C2 | B23: Objective — exam findings, vitals, and relevant test results documented | D23: =IF(C23="✓ Met",1,IF(C23="△ Partial",0.5,IF(C23="✗ Not Met",0,IF(C23="N/A","",""))))
A24: C3 | B24: Assessment — each diagnosis explicitly assessed with clinical reasoning | D24: =IF(C24="✓ Met",1,IF(C24="△ Partial",0.5,IF(C24="✗ Not Met",0,IF(C24="N/A","",""))))
A25: C4 | B25: Plan — treatment plan documented (medication / referral / testing / follow-up) | D25: =IF(C25="✓ Met",1,IF(C25="△ Partial",0.5,IF(C25="✗ Not Met",0,IF(C25="N/A","",""))))
A27: D · HCC Capture (2 items)
A28: D1 | B28: Prior-year HCCs recaptured (or explicitly resolved with rationale) | D28: =IF(C28="✓ Met",1,IF(C28="△ Partial",0.5,IF(C28="✗ Not Met",0,IF(C28="N/A","",""))))
A29: D2 | B29: Suspected undocumented chronic conditions captured with support | D29: =IF(C29="✓ Met",1,IF(C29="△ Partial",0.5,IF(C29="✗ Not Met",0,IF(C29="N/A","",""))))
A31: E · Documentation Supporting Quality Measures (2 items)
A32: E1 | B32: Screening / measure results documented with specific values (PHQ-9, GAD-7, BMI, BP, HbA1c) — not just 'screened' or 'normal' | D32: =IF(C32="✓ Met",1,IF(C32="△ Partial",0.5,IF(C32="✗ Not Met",0,IF(C32="N/A","",""))))
A33: E2 | B33: Follow-up plan documented when a screening is positive or a result is abnormal (positive PHQ-9 → depression plan; elevated BMI → nutrition counseling) | D33: =IF(C33="✓ Met",1,IF(C33="△ Partial",0.5,IF(C33="✗ Not Met",0,IF(C33="N/A","",""))))
A36: SUMMARY
A37: § | B37: Category | D37: % Met
A38: A | B38: Diagnosis Accuracy | C38: =COUNTIF(C10:C13,"✓ Met")+COUNTIF(C10:C13,"△ Partial")+COUNTIF(C10:C13,"✗ Not Met") | D38: =IFERROR(SUM(D10:D13)/C38,"")
A39: B | B39: Documentation Specificity | C39: =COUNTIF(C16:C19,"✓ Met")+COUNTIF(C16:C19,"△ Partial")+COUNTIF(C16:C19,"✗ Not Met") | D39: =IFERROR(SUM(D16:D19)/C39,"")
A40: C | B40: SOAP Note Structure | C40: =COUNTIF(C22:C25,"✓ Met")+COUNTIF(C22:C25,"△ Partial")+COUNTIF(C22:C25,"✗ Not Met") | D40: =IFERROR(SUM(D22:D25)/C40,"")
A41: D | B41: HCC Capture | C41: =COUNTIF(C28:C29,"✓ Met")+COUNTIF(C28:C29,"△ Partial")+COUNTIF(C28:C29,"✗ Not Met") | D41: =IFERROR(SUM(D28:D29)/C41,"")
A42: E | B42: Documentation Supporting Quality Measures | C42: =COUNTIF(C32:C33,"✓ Met")+COUNTIF(C32:C33,"△ Partial")+COUNTIF(C32:C33,"✗ Not Met") | D42: =IFERROR(SUM(D32:D33)/C42,"")
A44: OVERALL COMPLIANCE | D44: =IFERROR(SUMPRODUCT(D38:D42,C38:C42)/SUM(C38:C42),"")
A45: PERFORMANCE BAND | D45: =IF(D44="","",IF(D44>=0.95,"Excellent",IF(D44>=0.90,"Meets Expectations",IF(D44>=0.80,"Needs Improvement","Corrective Education Required"))))

Sheet Claim 06
A1: Clinical Documentation Audit
A2: One chart per sheet · tick each item · scoring & rating are automatic
A4: Provider: | C4: Date of Service: | E4: How to audit a claim 1. Click a Claim 01–10 tab (bottom of the workbook) 2. Fill yellow header + ratings — auto-scores 3. Move to the next Claim tab · repeat Global metrics roll up automatically • Open the Provider Metrics tab — it pulls the 10 claim scores live from the Claim tabs so you see the running provider average. Start a new provider (after 10 claims) 1. Ctrl+click Claim 01 through Claim 10 to group them 2. Select the yellow header + rating + note cells on any tab 3. Press Delete → all 10 tabs clear at once 4. Right-click any tab → Ungroup Sheets
A5: Claim Number: | C5: Auditor:
A6: Category: | C6: Payer:
A7: Date of audit:
A8: § | B8: Documentation element | D8: Pts
A9: A · Diagnosis Accuracy (4 items)
A10: A1 | B10: All reported diagnoses are clinically supported in the note | D10: =IF(C10="✓ Met",1,IF(C10="△ Partial",0.5,IF(C10="✗ Not Met",0,IF(C10="N/A","",""))))
A11: A2 | B11: Chronic conditions actively addressed at this visit (not just carried forward) | D11: =IF(C11="✓ Met",1,IF(C11="△ Partial",0.5,IF(C11="✗ Not Met",0,IF(C11="N/A","",""))))
A12: A3 | B12: No unsupported or resolved conditions billed as active | D12: =IF(C12="✓ Met",1,IF(C12="△ Partial",0.5,IF(C12="✗ Not Met",0,IF(C12="N/A","",""))))
A13: A4 | B13: Problem list matches today's assessment & plan | D13: =IF(C13="✓ Met",1,IF(C13="△ Partial",0.5,IF(C13="✗ Not Met",0,IF(C13="N/A","",""))))
A15: B · Documentation Specificity (4 items)
A16: B1 | B16: ICD-10 codes at highest available specificity (avoid 'unspecified') | D16: =IF(C16="✓ Met",1,IF(C16="△ Partial",0.5,IF(C16="✗ Not Met",0,IF(C16="N/A","",""))))
A17: B2 | B17: Diabetes: type + complications + control specified | D17: =IF(C17="✓ Met",1,IF(C17="△ Partial",0.5,IF(C17="✗ Not Met",0,IF(C17="N/A","",""))))
A18: B3 | B18: S / O / A / P sections tell one consistent clinical story | D18: =IF(C18="✓ Met",1,IF(C18="△ Partial",0.5,IF(C18="✗ Not Met",0,IF(C18="N/A","",""))))
A19: B4 | B19: Note signed, dated, and closed by the rendering provider | D19: =IF(C19="✓ Met",1,IF(C19="△ Partial",0.5,IF(C19="✗ Not Met",0,IF(C19="N/A","",""))))
A21: C · SOAP Note Structure (4 items)
A22: C1 | B22: Subjective — patient's history, symptoms, and concerns clearly documented | D22: =IF(C22="✓ Met",1,IF(C22="△ Partial",0.5,IF(C22="✗ Not Met",0,IF(C22="N/A","",""))))
A23: C2 | B23: Objective — exam findings, vitals, and relevant test results documented | D23: =IF(C23="✓ Met",1,IF(C23="△ Partial",0.5,IF(C23="✗ Not Met",0,IF(C23="N/A","",""))))
A24: C3 | B24: Assessment — each diagnosis explicitly assessed with clinical reasoning | D24: =IF(C24="✓ Met",1,IF(C24="△ Partial",0.5,IF(C24="✗ Not Met",0,IF(C24="N/A","",""))))
A25: C4 | B25: Plan — treatment plan documented (medication / referral / testing / follow-up) | D25: =IF(C25="✓ Met",1,IF(C25="△ Partial",0.5,IF(C25="✗ Not Met",0,IF(C25="N/A","",""))))
A27: D · HCC Capture (2 items)
A28: D1 | B28: Prior-year HCCs recaptured (or explicitly resolved with rationale) | D28: =IF(C28="✓ Met",1,IF(C28="△ Partial",0.5,IF(C28="✗ Not Met",0,IF(C28="N/A","",""))))
A29: D2 | B29: Suspected undocumented chronic conditions captured with support | D29: =IF(C29="✓ Met",1,IF(C29="△ Partial",0.5,IF(C29="✗ Not Met",0,IF(C29="N/A","",""))))
A31: E · Documentation Supporting Quality Measures (2 items)
A32: E1 | B32: Screening / measure results documented with specific values (PHQ-9, GAD-7, BMI, BP, HbA1c) — not just 'screened' or 'normal' | D32: =IF(C32="✓ Met",1,IF(C32="△ Partial",0.5,IF(C32="✗ Not Met",0,IF(C32="N/A","",""))))
A33: E2 | B33: Follow-up plan documented when a screening is positive or a result is abnormal (positive PHQ-9 → depression plan; elevated BMI → nutrition counseling) | D33: =IF(C33="✓ Met",1,IF(C33="△ Partial",0.5,IF(C33="✗ Not Met",0,IF(C33="N/A","",""))))
A36: SUMMARY
A37: § | B37: Category | D37: % Met
A38: A | B38: Diagnosis Accuracy | C38: =COUNTIF(C10:C13,"✓ Met")+COUNTIF(C10:C13,"△ Partial")+COUNTIF(C10:C13,"✗ Not Met") | D38: =IFERROR(SUM(D10:D13)/C38,"")
A39: B | B39: Documentation Specificity | C39: =COUNTIF(C16:C19,"✓ Met")+COUNTIF(C16:C19,"△ Partial")+COUNTIF(C16:C19,"✗ Not Met") | D39: =IFERROR(SUM(D16:D19)/C39,"")
A40: C | B40: SOAP Note Structure | C40: =COUNTIF(C22:C25,"✓ Met")+COUNTIF(C22:C25,"△ Partial")+COUNTIF(C22:C25,"✗ Not Met") | D40: =IFERROR(SUM(D22:D25)/C40,"")
A41: D | B41: HCC Capture | C41: =COUNTIF(C28:C29,"✓ Met")+COUNTIF(C28:C29,"△ Partial")+COUNTIF(C28:C29,"✗ Not Met") | D41: =IFERROR(SUM(D28:D29)/C41,"")
A42: E | B42: Documentation Supporting Quality Measures | C42: =COUNTIF(C32:C33,"✓ Met")+COUNTIF(C32:C33,"△ Partial")+COUNTIF(C32:C33,"✗ Not Met") | D42: =IFERROR(SUM(D32:D33)/C42,"")
A44: OVERALL COMPLIANCE | D44: =IFERROR(SUMPRODUCT(D38:D42,C38:C42)/SUM(C38:C42),"")
A45: PERFORMANCE BAND | D45: =IF(D44="","",IF(D44>=0.95,"Excellent",IF(D44>=0.90,"Meets Expectations",IF(D44>=0.80,"Needs Improvement","Corrective Education Required"))))

Sheet Claim 07
A1: Clinical Documentation Audit
A2: One chart per sheet · tick each item · scoring & rating are automatic
A4: Provider: | C4: Date of Service: | E4: How to audit a claim 1. Click a Claim 01–10 tab (bottom of the workbook) 2. Fill yellow header + ratings — auto-scores 3. Move to the next Claim tab · repeat Global metrics roll up automatically • Open the Provider Metrics tab — it pulls the 10 claim scores live from the Claim tabs so you see the running provider average. Start a new provider (after 10 claims) 1. Ctrl+click Claim 01 through Claim 10 to group them 2. Select the yellow header + rating + note cells on any tab 3. Press Delete → all 10 tabs clear at once 4. Right-click any tab → Ungroup Sheets
A5: Claim Number: | C5: Auditor:
A6: Category: | C6: Payer:
A7: Date of audit:
A8: § | B8: Documentation element | D8: Pts
A9: A · Diagnosis Accuracy (4 items)
A10: A1 | B10: All reported diagnoses are clinically supported in the note | D10: =IF(C10="✓ Met",1,IF(C10="△ Partial",0.5,IF(C10="✗ Not Met",0,IF(C10="N/A","",""))))
A11: A2 | B11: Chronic conditions actively addressed at this visit (not just carried forward) | D11: =IF(C11="✓ Met",1,IF(C11="△ Partial",0.5,IF(C11="✗ Not Met",0,IF(C11="N/A","",""))))
A12: A3 | B12: No unsupported or resolved conditions billed as active | D12: =IF(C12="✓ Met",1,IF(C12="△ Partial",0.5,IF(C12="✗ Not Met",0,IF(C12="N/A","",""))))
A13: A4 | B13: Problem list matches today's assessment & plan | D13: =IF(C13="✓ Met",1,IF(C13="△ Partial",0.5,IF(C13="✗ Not Met",0,IF(C13="N/A","",""))))
A15: B · Documentation Specificity (4 items)
A16: B1 | B16: ICD-10 codes at highest available specificity (avoid 'unspecified') | D16: =IF(C16="✓ Met",1,IF(C16="△ Partial",0.5,IF(C16="✗ Not Met",0,IF(C16="N/A","",""))))
A17: B2 | B17: Diabetes: type + complications + control specified | D17: =IF(C17="✓ Met",1,IF(C17="△ Partial",0.5,IF(C17="✗ Not Met",0,IF(C17="N/A","",""))))
A18: B3 | B18: S / O / A / P sections tell one consistent clinical story | D18: =IF(C18="✓ Met",1,IF(C18="△ Partial",0.5,IF(C18="✗ Not Met",0,IF(C18="N/A","",""))))
A19: B4 | B19: Note signed, dated, and closed by the rendering provider | D19: =IF(C19="✓ Met",1,IF(C19="△ Partial",0.5,IF(C19="✗ Not Met",0,IF(C19="N/A","",""))))
A21: C · SOAP Note Structure (4 items)
A22: C1 | B22: Subjective — patient's history, symptoms, and concerns clearly documented | D22: =IF(C22="✓ Met",1,IF(C22="△ Partial",0.5,IF(C22="✗ Not Met",0,IF(C22="N/A","",""))))
A23: C2 | B23: Objective — exam findings, vitals, and relevant test results documented | D23: =IF(C23="✓ Met",1,IF(C23="△ Partial",0.5,IF(C23="✗ Not Met",0,IF(C23="N/A","",""))))
A24: C3 | B24: Assessment — each diagnosis explicitly assessed with clinical reasoning | D24: =IF(C24="✓ Met",1,IF(C24="△ Partial",0.5,IF(C24="✗ Not Met",0,IF(C24="N/A","",""))))
A25: C4 | B25: Plan — treatment plan documented (medication / referral / testing / follow-up) | D25: =IF(C25="✓ Met",1,IF(C25="△ Partial",0.5,IF(C25="✗ Not Met",0,IF(C25="N/A","",""))))
A27: D · HCC Capture (2 items)
A28: D1 | B28: Prior-year HCCs recaptured (or explicitly resolved with rationale) | D28: =IF(C28="✓ Met",1,IF(C28="△ Partial",0.5,IF(C28="✗ Not Met",0,IF(C28="N/A","",""))))
A29: D2 | B29: Suspected undocumented chronic conditions captured with support | D29: =IF(C29="✓ Met",1,IF(C29="△ Partial",0.5,IF(C29="✗ Not Met",0,IF(C29="N/A","",""))))
A31: E · Documentation Supporting Quality Measures (2 items)
A32: E1 | B32: Screening / measure results documented with specific values (PHQ-9, GAD-7, BMI, BP, HbA1c) — not just 'screened' or 'normal' | D32: =IF(C32="✓ Met",1,IF(C32="△ Partial",0.5,IF(C32="✗ Not Met",0,IF(C32="N/A","",""))))
A33: E2 | B33: Follow-up plan documented when a screening is positive or a result is abnormal (positive PHQ-9 → depression plan; elevated BMI → nutrition counseling) | D33: =IF(C33="✓ Met",1,IF(C33="△ Partial",0.5,IF(C33="✗ Not Met",0,IF(C33="N/A","",""))))
A36: SUMMARY
A37: § | B37: Category | D37: % Met
A38: A | B38: Diagnosis Accuracy | C38: =COUNTIF(C10:C13,"✓ Met")+COUNTIF(C10:C13,"△ Partial")+COUNTIF(C10:C13,"✗ Not Met") | D38: =IFERROR(SUM(D10:D13)/C38,"")
A39: B | B39: Documentation Specificity | C39: =COUNTIF(C16:C19,"✓ Met")+COUNTIF(C16:C19,"△ Partial")+COUNTIF(C16:C19,"✗ Not Met") | D39: =IFERROR(SUM(D16:D19)/C39,"")
A40: C | B40: SOAP Note Structure | C40: =COUNTIF(C22:C25,"✓ Met")+COUNTIF(C22:C25,"△ Partial")+COUNTIF(C22:C25,"✗ Not Met") | D40: =IFERROR(SUM(D22:D25)/C40,"")
A41: D | B41: HCC Capture | C41: =COUNTIF(C28:C29,"✓ Met")+COUNTIF(C28:C29,"△ Partial")+COUNTIF(C28:C29,"✗ Not Met") | D41: =IFERROR(SUM(D28:D29)/C41,"")
A42: E | B42: Documentation Supporting Quality Measures | C42: =COUNTIF(C32:C33,"✓ Met")+COUNTIF(C32:C33,"△ Partial")+COUNTIF(C32:C33,"✗ Not Met") | D42: =IFERROR(SUM(D32:D33)/C42,"")
A44: OVERALL COMPLIANCE | D44: =IFERROR(SUMPRODUCT(D38:D42,C38:C42)/SUM(C38:C42),"")
A45: PERFORMANCE BAND | D45: =IF(D44="","",IF(D44>=0.95,"Excellent",IF(D44>=0.90,"Meets Expectations",IF(D44>=0.80,"Needs Improvement","Corrective Education Required"))))

Sheet Claim 08
A1: Clinical Documentation Audit
A2: One chart per sheet · tick each item · scoring & rating are automatic
A4: Provider: | C4: Date of Service: | E4: How to audit a claim 1. Click a Claim 01–10 tab (bottom of the workbook) 2. Fill yellow header + ratings — auto-scores 3. Move to the next Claim tab · repeat Global metrics roll up automatically • Open the Provider Metrics tab — it pulls the 10 claim scores live from the Claim tabs so you see the running provider average. Start a new provider (after 10 claims) 1. Ctrl+click Claim 01 through Claim 10 to group them 2. Select the yellow header + rating + note cells on any tab 3. Press Delete → all 10 tabs clear at once 4. Right-click any tab → Ungroup Sheets
A5: Claim Number: | C5: Auditor:
A6: Category: | C6: Payer:
A7: Date of audit:
A8: § | B8: Documentation element | D8: Pts
A9: A · Diagnosis Accuracy (4 items)
A10: A1 | B10: All reported diagnoses are clinically supported in the note | D10: =IF(C10="✓ Met",1,IF(C10="△ Partial",0.5,IF(C10="✗ Not Met",0,IF(C10="N/A","",""))))
A11: A2 | B11: Chronic conditions actively addressed at this visit (not just carried forward) | D11: =IF(C11="✓ Met",1,IF(C11="△ Partial",0.5,IF(C11="✗ Not Met",0,IF(C11="N/A","",""))))
A12: A3 | B12: No unsupported or resolved conditions billed as active | D12: =IF(C12="✓ Met",1,IF(C12="△ Partial",0.5,IF(C12="✗ Not Met",0,IF(C12="N/A","",""))))
A13: A4 | B13: Problem list matches today's assessment & plan | D13: =IF(C13="✓ Met",1,IF(C13="△ Partial",0.5,IF(C13="✗ Not Met",0,IF(C13="N/A","",""))))
A15: B · Documentation Specificity (4 items)
A16: B1 | B16: ICD-10 codes at highest available specificity (avoid 'unspecified') | D16: =IF(C16="✓ Met",1,IF(C16="△ Partial",0.5,IF(C16="✗ Not Met",0,IF(C16="N/A","",""))))
A17: B2 | B17: Diabetes: type + complications + control specified | D17: =IF(C17="✓ Met",1,IF(C17="△ Partial",0.5,IF(C17="✗ Not Met",0,IF(C17="N/A","",""))))
A18: B3 | B18: S / O / A / P sections tell one consistent clinical story | D18: =IF(C18="✓ Met",1,IF(C18="△ Partial",0.5,IF(C18="✗ Not Met",0,IF(C18="N/A","",""))))
A19: B4 | B19: Note signed, dated, and closed by the rendering provider | D19: =IF(C19="✓ Met",1,IF(C19="△ Partial",0.5,IF(C19="✗ Not Met",0,IF(C19="N/A","",""))))
A21: C · SOAP Note Structure (4 items)
A22: C1 | B22: Subjective — patient's history, symptoms, and concerns clearly documented | D22: =IF(C22="✓ Met",1,IF(C22="△ Partial",0.5,IF(C22="✗ Not Met",0,IF(C22="N/A","",""))))
A23: C2 | B23: Objective — exam findings, vitals, and relevant test results documented | D23: =IF(C23="✓ Met",1,IF(C23="△ Partial",0.5,IF(C23="✗ Not Met",0,IF(C23="N/A","",""))))
A24: C3 | B24: Assessment — each diagnosis explicitly assessed with clinical reasoning | D24: =IF(C24="✓ Met",1,IF(C24="△ Partial",0.5,IF(C24="✗ Not Met",0,IF(C24="N/A","",""))))
A25: C4 | B25: Plan — treatment plan documented (medication / referral / testing / follow-up) | D25: =IF(C25="✓ Met",1,IF(C25="△ Partial",0.5,IF(C25="✗ Not Met",0,IF(C25="N/A","",""))))
A27: D · HCC Capture (2 items)
A28: D1 | B28: Prior-year HCCs recaptured (or explicitly resolved with rationale) | D28: =IF(C28="✓ Met",1,IF(C28="△ Partial",0.5,IF(C28="✗ Not Met",0,IF(C28="N/A","",""))))
A29: D2 | B29: Suspected undocumented chronic conditions captured with support | D29: =IF(C29="✓ Met",1,IF(C29="△ Partial",0.5,IF(C29="✗ Not Met",0,IF(C29="N/A","",""))))
A31: E · Documentation Supporting Quality Measures (2 items)
A32: E1 | B32: Screening / measure results documented with specific values (PHQ-9, GAD-7, BMI, BP, HbA1c) — not just 'screened' or 'normal' | D32: =IF(C32="✓ Met",1,IF(C32="△ Partial",0.5,IF(C32="✗ Not Met",0,IF(C32="N/A","",""))))
A33: E2 | B33: Follow-up plan documented when a screening is positive or a result is abnormal (positive PHQ-9 → depression plan; elevated BMI → nutrition counseling) | D33: =IF(C33="✓ Met",1,IF(C33="△ Partial",0.5,IF(C33="✗ Not Met",0,IF(C33="N/A","",""))))
A36: SUMMARY
A37: § | B37: Category | D37: % Met
A38: A | B38: Diagnosis Accuracy | C38: =COUNTIF(C10:C13,"✓ Met")+COUNTIF(C10:C13,"△ Partial")+COUNTIF(C10:C13,"✗ Not Met") | D38: =IFERROR(SUM(D10:D13)/C38,"")
A39: B | B39: Documentation Specificity | C39: =COUNTIF(C16:C19,"✓ Met")+COUNTIF(C16:C19,"△ Partial")+COUNTIF(C16:C19,"✗ Not Met") | D39: =IFERROR(SUM(D16:D19)/C39,"")
A40: C | B40: SOAP Note Structure | C40: =COUNTIF(C22:C25,"✓ Met")+COUNTIF(C22:C25,"△ Partial")+COUNTIF(C22:C25,"✗ Not Met") | D40: =IFERROR(SUM(D22:D25)/C40,"")
A41: D | B41: HCC Capture | C41: =COUNTIF(C28:C29,"✓ Met")+COUNTIF(C28:C29,"△ Partial")+COUNTIF(C28:C29,"✗ Not Met") | D41: =IFERROR(SUM(D28:D29)/C41,"")
A42: E | B42: Documentation Supporting Quality Measures | C42: =COUNTIF(C32:C33,"✓ Met")+COUNTIF(C32:C33,"△ Partial")+COUNTIF(C32:C33,"✗ Not Met") | D42: =IFERROR(SUM(D32:D33)/C42,"")
A44: OVERALL COMPLIANCE | D44: =IFERROR(SUMPRODUCT(D38:D42,C38:C42)/SUM(C38:C42),"")
A45: PERFORMANCE BAND | D45: =IF(D44="","",IF(D44>=0.95,"Excellent",IF(D44>=0.90,"Meets Expectations",IF(D44>=0.80,"Needs Improvement","Corrective Education Required"))))

Sheet Claim 09
A1: Clinical Documentation Audit
A2: One chart per sheet · tick each item · scoring & rating are automatic
A4: Provider: | C4: Date of Service: | E4: How to audit a claim 1. Click a Claim 01–10 tab (bottom of the workbook) 2. Fill yellow header + ratings — auto-scores 3. Move to the next Claim tab · repeat Global metrics roll up automatically • Open the Provider Metrics tab — it pulls the 10 claim scores live from the Claim tabs so you see the running provider average. Start a new provider (after 10 claims) 1. Ctrl+click Claim 01 through Claim 10 to group them 2. Select the yellow header + rating + note cells on any tab 3. Press Delete → all 10 tabs clear at once 4. Right-click any tab → Ungroup Sheets
A5: Claim Number: | C5: Auditor:
A6: Category: | C6: Payer:
A7: Date of audit:
A8: § | B8: Documentation element | D8: Pts
A9: A · Diagnosis Accuracy (4 items)
A10: A1 | B10: All reported diagnoses are clinically supported in the note | D10: =IF(C10="✓ Met",1,IF(C10="△ Partial",0.5,IF(C10="✗ Not Met",0,IF(C10="N/A","",""))))
A11: A2 | B11: Chronic conditions actively addressed at this visit (not just carried forward) | D11: =IF(C11="✓ Met",1,IF(C11="△ Partial",0.5,IF(C11="✗ Not Met",0,IF(C11="N/A","",""))))
A12: A3 | B12: No unsupported or resolved conditions billed as active | D12: =IF(C12="✓ Met",1,IF(C12="△ Partial",0.5,IF(C12="✗ Not Met",0,IF(C12="N/A","",""))))
A13: A4 | B13: Problem list matches today's assessment & plan | D13: =IF(C13="✓ Met",1,IF(C13="△ Partial",0.5,IF(C13="✗ Not Met",0,IF(C13="N/A","",""))))
A15: B · Documentation Specificity (4 items)
A16: B1 | B16: ICD-10 codes at highest available specificity (avoid 'unspecified') | D16: =IF(C16="✓ Met",1,IF(C16="△ Partial",0.5,IF(C16="✗ Not Met",0,IF(C16="N/A","",""))))
A17: B2 | B17: Diabetes: type + complications + control specified | D17: =IF(C17="✓ Met",1,IF(C17="△ Partial",0.5,IF(C17="✗ Not Met",0,IF(C17="N/A","",""))))
A18: B3 | B18: S / O / A / P sections tell one consistent clinical story | D18: =IF(C18="✓ Met",1,IF(C18="△ Partial",0.5,IF(C18="✗ Not Met",0,IF(C18="N/A","",""))))
A19: B4 | B19: Note signed, dated, and closed by the rendering provider | D19: =IF(C19="✓ Met",1,IF(C19="△ Partial",0.5,IF(C19="✗ Not Met",0,IF(C19="N/A","",""))))
A21: C · SOAP Note Structure (4 items)
A22: C1 | B22: Subjective — patient's history, symptoms, and concerns clearly documented | D22: =IF(C22="✓ Met",1,IF(C22="△ Partial",0.5,IF(C22="✗ Not Met",0,IF(C22="N/A","",""))))
A23: C2 | B23: Objective — exam findings, vitals, and relevant test results documented | D23: =IF(C23="✓ Met",1,IF(C23="△ Partial",0.5,IF(C23="✗ Not Met",0,IF(C23="N/A","",""))))
A24: C3 | B24: Assessment — each diagnosis explicitly assessed with clinical reasoning | D24: =IF(C24="✓ Met",1,IF(C24="△ Partial",0.5,IF(C24="✗ Not Met",0,IF(C24="N/A","",""))))
A25: C4 | B25: Plan — treatment plan documented (medication / referral / testing / follow-up) | D25: =IF(C25="✓ Met",1,IF(C25="△ Partial",0.5,IF(C25="✗ Not Met",0,IF(C25="N/A","",""))))
A27: D · HCC Capture (2 items)
A28: D1 | B28: Prior-year HCCs recaptured (or explicitly resolved with rationale) | D28: =IF(C28="✓ Met",1,IF(C28="△ Partial",0.5,IF(C28="✗ Not Met",0,IF(C28="N/A","",""))))
A29: D2 | B29: Suspected undocumented chronic conditions captured with support | D29: =IF(C29="✓ Met",1,IF(C29="△ Partial",0.5,IF(C29="✗ Not Met",0,IF(C29="N/A","",""))))
A31: E · Documentation Supporting Quality Measures (2 items)
A32: E1 | B32: Screening / measure results documented with specific values (PHQ-9, GAD-7, BMI, BP, HbA1c) — not just 'screened' or 'normal' | D32: =IF(C32="✓ Met",1,IF(C32="△ Partial",0.5,IF(C32="✗ Not Met",0,IF(C32="N/A","",""))))
A33: E2 | B33: Follow-up plan documented when a screening is positive or a result is abnormal (positive PHQ-9 → depression plan; elevated BMI → nutrition counseling) | D33: =IF(C33="✓ Met",1,IF(C33="△ Partial",0.5,IF(C33="✗ Not Met",0,IF(C33="N/A","",""))))
A36: SUMMARY
A37: § | B37: Category | D37: % Met
A38: A | B38: Diagnosis Accuracy | C38: =COUNTIF(C10:C13,"✓ Met")+COUNTIF(C10:C13,"△ Partial")+COUNTIF(C10:C13,"✗ Not Met") | D38: =IFERROR(SUM(D10:D13)/C38,"")
A39: B | B39: Documentation Specificity | C39: =COUNTIF(C16:C19,"✓ Met")+COUNTIF(C16:C19,"△ Partial")+COUNTIF(C16:C19,"✗ Not Met") | D39: =IFERROR(SUM(D16:D19)/C39,"")
A40: C | B40: SOAP Note Structure | C40: =COUNTIF(C22:C25,"✓ Met")+COUNTIF(C22:C25,"△ Partial")+COUNTIF(C22:C25,"✗ Not Met") | D40: =IFERROR(SUM(D22:D25)/C40,"")
A41: D | B41: HCC Capture | C41: =COUNTIF(C28:C29,"✓ Met")+COUNTIF(C28:C29,"△ Partial")+COUNTIF(C28:C29,"✗ Not Met") | D41: =IFERROR(SUM(D28:D29)/C41,"")
A42: E | B42: Documentation Supporting Quality Measures | C42: =COUNTIF(C32:C33,"✓ Met")+COUNTIF(C32:C33,"△ Partial")+COUNTIF(C32:C33,"✗ Not Met") | D42: =IFERROR(SUM(D32:D33)/C42,"")
A44: OVERALL COMPLIANCE | D44: =IFERROR(SUMPRODUCT(D38:D42,C38:C42)/SUM(C38:C42),"")
A45: PERFORMANCE BAND | D45: =IF(D44="","",IF(D44>=0.95,"Excellent",IF(D44>=0.90,"Meets Expectations",IF(D44>=0.80,"Needs Improvement","Corrective Education Required"))))

Sheet Claim 10
A1: Clinical Documentation Audit
A2: One chart per sheet · tick each item · scoring & rating are automatic
A4: Provider: | C4: Date of Service: | E4: How to audit a claim 1. Click a Claim 01–10 tab (bottom of the workbook) 2. Fill yellow header + ratings — auto-scores 3. Move to the next Claim tab · repeat Global metrics roll up automatically • Open the Provider Metrics tab — it pulls the 10 claim scores live from the Claim tabs so you see the running provider average. Start a new provider (after 10 claims) 1. Ctrl+click Claim 01 through Claim 10 to group them 2. Select the yellow header + rating + note cells on any tab 3. Press Delete → all 10 tabs clear at once 4. Right-click any tab → Ungroup Sheets
A5: Claim Number: | C5: Auditor:
A6: Category: | C6: Payer:
A7: Date of audit:
A8: § | B8: Documentation element | D8: Pts
A9: A · Diagnosis Accuracy (4 items)
A10: A1 | B10: All reported diagnoses are clinically supported in the note | D10: =IF(C10="✓ Met",1,IF(C10="△ Partial",0.5,IF(C10="✗ Not Met",0,IF(C10="N/A","",""))))
A11: A2 | B11: Chronic conditions actively addressed at this visit (not just carried forward) | D11: =IF(C11="✓ Met",1,IF(C11="△ Partial",0.5,IF(C11="✗ Not Met",0,IF(C11="N/A","",""))))
A12: A3 | B12: No unsupported or resolved conditions billed as active | D12: =IF(C12="✓ Met",1,IF(C12="△ Partial",0.5,IF(C12="✗ Not Met",0,IF(C12="N/A","",""))))
A13: A4 | B13: Problem list matches today's assessment & plan | D13: =IF(C13="✓ Met",1,IF(C13="△ Partial",0.5,IF(C13="✗ Not Met",0,IF(C13="N/A","",""))))
A15: B · Documentation Specificity (4 items)
A16: B1 | B16: ICD-10 codes at highest available specificity (avoid 'unspecified') | D16: =IF(C16="✓ Met",1,IF(C16="△ Partial",0.5,IF(C16="✗ Not Met",0,IF(C16="N/A","",""))))
A17: B2 | B17: Diabetes: type + complications + control specified | D17: =IF(C17="✓ Met",1,IF(C17="△ Partial",0.5,IF(C17="✗ Not Met",0,IF(C17="N/A","",""))))
A18: B3 | B18: S / O / A / P sections tell one consistent clinical story | D18: =IF(C18="✓ Met",1,IF(C18="△ Partial",0.5,IF(C18="✗ Not Met",0,IF(C18="N/A","",""))))
A19: B4 | B19: Note signed, dated, and closed by the rendering provider | D19: =IF(C19="✓ Met",1,IF(C19="△ Partial",0.5,IF(C19="✗ Not Met",0,IF(C19="N/A","",""))))
A21: C · SOAP Note Structure (4 items)
A22: C1 | B22: Subjective — patient's history, symptoms, and concerns clearly documented | D22: =IF(C22="✓ Met",1,IF(C22="△ Partial",0.5,IF(C22="✗ Not Met",0,IF(C22="N/A","",""))))
A23: C2 | B23: Objective — exam findings, vitals, and relevant test results documented | D23: =IF(C23="✓ Met",1,IF(C23="△ Partial",0.5,IF(C23="✗ Not Met",0,IF(C23="N/A","",""))))
A24: C3 | B24: Assessment — each diagnosis explicitly assessed with clinical reasoning | D24: =IF(C24="✓ Met",1,IF(C24="△ Partial",0.5,IF(C24="✗ Not Met",0,IF(C24="N/A","",""))))
A25: C4 | B25: Plan — treatment plan documented (medication / referral / testing / follow-up) | D25: =IF(C25="✓ Met",1,IF(C25="△ Partial",0.5,IF(C25="✗ Not Met",0,IF(C25="N/A","",""))))
A27: D · HCC Capture (2 items)
A28: D1 | B28: Prior-year HCCs recaptured (or explicitly resolved with rationale) | D28: =IF(C28="✓ Met",1,IF(C28="△ Partial",0.5,IF(C28="✗ Not Met",0,IF(C28="N/A","",""))))
A29: D2 | B29: Suspected undocumented chronic conditions captured with support | D29: =IF(C29="✓ Met",1,IF(C29="△ Partial",0.5,IF(C29="✗ Not Met",0,IF(C29="N/A","",""))))
A31: E · Documentation Supporting Quality Measures (2 items)
A32: E1 | B32: Screening / measure results documented with specific values (PHQ-9, GAD-7, BMI, BP, HbA1c) — not just 'screened' or 'normal' | D32: =IF(C32="✓ Met",1,IF(C32="△ Partial",0.5,IF(C32="✗ Not Met",0,IF(C32="N/A","",""))))
A33: E2 | B33: Follow-up plan documented when a screening is positive or a result is abnormal (positive PHQ-9 → depression plan; elevated BMI → nutrition counseling) | D33: =IF(C33="✓ Met",1,IF(C33="△ Partial",0.5,IF(C33="✗ Not Met",0,IF(C33="N/A","",""))))
A36: SUMMARY
A37: § | B37: Category | D37: % Met
A38: A | B38: Diagnosis Accuracy | C38: =COUNTIF(C10:C13,"✓ Met")+COUNTIF(C10:C13,"△ Partial")+COUNTIF(C10:C13,"✗ Not Met") | D38: =IFERROR(SUM(D10:D13)/C38,"")
A39: B | B39: Documentation Specificity | C39: =COUNTIF(C16:C19,"✓ Met")+COUNTIF(C16:C19,"△ Partial")+COUNTIF(C16:C19,"✗ Not Met") | D39: =IFERROR(SUM(D16:D19)/C39,"")
A40: C | B40: SOAP Note Structure | C40: =COUNTIF(C22:C25,"✓ Met")+COUNTIF(C22:C25,"△ Partial")+COUNTIF(C22:C25,"✗ Not Met") | D40: =IFERROR(SUM(D22:D25)/C40,"")
A41: D | B41: HCC Capture | C41: =COUNTIF(C28:C29,"✓ Met")+COUNTIF(C28:C29,"△ Partial")+COUNTIF(C28:C29,"✗ Not Met") | D41: =IFERROR(SUM(D28:D29)/C41,"")
A42: E | B42: Documentation Supporting Quality Measures | C42: =COUNTIF(C32:C33,"✓ Met")+COUNTIF(C32:C33,"△ Partial")+COUNTIF(C32:C33,"✗ Not Met") | D42: =IFERROR(SUM(D32:D33)/C42,"")
A44: OVERALL COMPLIANCE | D44: =IFERROR(SUMPRODUCT(D38:D42,C38:C42)/SUM(C38:C42),"")
A45: PERFORMANCE BAND | D45: =IF(D44="","",IF(D44>=0.95,"Excellent",IF(D44>=0.90,"Meets Expectations",IF(D44>=0.80,"Needs Improvement","Corrective Education Required"))))

Sheet Audit Log
A1: Audit Log — Rolling record | L1: Provider Metrics
A2: One row per chart audited. Log each chart when you finish it — this is your working history. | L2: Pick a provider and month → rollup shows below
A4: Audit Date | B4: Provider | C4: Claim Number | D4: DOS | E4: Category | F4: Compliance % | G4: Rating | H4: Deficiencies | I4: Follow-Up / Notes | L4: Provider:
A5: 46206 | B5: Dr. Rivera | C5: CLM-2026-001 | D5: 46201 | E5: Diabetes | F5: 0.96 | G5: Excellent | H5: None | I5: Sample row · delete when starting real audits | L5: Audit Month:
A6: 46211 | B6: Dr. Rivera | C6: CLM-2026-002 | D6: 46203 | E6: Chronic Kidney Disease | F6: 0.92 | G6: Meets Expectations | H6: N18 unspecified | I6: Sample row · delete when starting real audits
A7: 46215 | B7: Dr. Colón | C7: CLM-2026-003 | D7: 46208 | E7: Diabetes | F7: 0.86 | G7: Needs Improvement | H7: E11.9 use, missing MEAT | I7: Sample row · delete when starting real audits | L7: Claims audited | M7: =SUMPRODUCT(($B$5:$B$200=$M$4)*ISNUMBER($A$5:$A$200)*(TEXT($A$5:$A$200,"yyyy-mm")=$M$5)*1)
