Workbook

Sheet Cover
A1: HealthProMed — Internal Clinical Documentation Audit
A2: Monthly provider audit workbook · Family Medicine · Internal Medicine · General Medicine
B4: Program owner | C4: Coding & Compliance — Revenue Integrity
B5: Cycle | C5: Monthly (charts drawn from prior month's encounters)
B6: Sample size | C6: 10 charts per provider per month
B7: Chart mix | C7: 3 Diabetes · 2 CKD · 2 AWV · 2 High RAF · 1 Random
B8: Scoring model | C8: Diagnosis 30% · Doc specificity 25% · MEAT 25% · HCC 10% · CPT II 10%
B9: Performance bands | C9: Excellent 95–100 · Meets 90–94 · Needs improvement 80–89 · Corrective <80
B10: Six-month targets | C10: -25% unspecified codes · +20% HCC specificity · +15% CPT II · 100% completion
B12: Workbook tabs
B13: 1. Provider Roster | C13: List of every provider being audited this cycle.
B14: 2. Chart Sample Log | C14: Every chart pulled for audit — one row per chart.
B15: 3. Audit Worksheet | C15: The 10-chart-per-provider audit form. Score each chart here.
B16: 4. MEAT Checklist | C16: Per-diagnosis MEAT validation (Monitor · Evaluate · Assess · Treat).
B17: 5. HCC / RAF Tracker | C17: HCC recapture + missed HCC opportunities.
B18: 6. CPT II Tracker | C18: CPT II reporting compliance and misses.
B19: 7. Scorecard | C19: Per-provider monthly score with weighted rollup.
B20: 8. Dashboard | C20: Monthly KPI summary + trend view.
B21: 9. Corrective Action | C21: Providers below 80% + re-audit tracking.
B22: 10. Reference | C22: MEAT criteria, high-risk dx list, CPT II priorities, code lists.

Sheet Provider Roster
A1: Provider Roster
A2: Every provider audited this cycle. Add rows as needed.
A4: Provider ID | B4: Provider Name | C4: Specialty | D4: Clinic / Site | E4: NPI | F4: Payer Mix (MA / Comm / Both) | G4: Active for Audit?
A5: FM-001 | B5: Dr. Provider One | C5: Family Medicine | D5: San Juan | E5: 1234567890 | F5: Both | G5: Yes
A6: FM-002 | B6: Dr. Provider Two | C6: Family Medicine | D6: Ponce | E6: 2345678901 | F6: MA | G6: Yes
A7: IM-001 | B7: Dr. Provider Three | C7: Internal Medicine | D7: Bayamón | E7: 3456789012 | F7: Both | G7: Yes
A8: IM-002 | B8: Dr. Provider Four | C8: Internal Medicine | D8: Caguas | E8: 4567890123 | F8: MA | G8: Yes
A9: GM-001 | B9: Dr. Provider Five | C9: General Medicine | D9: Mayagüez | E9: 5678901234 | F9: Comm | G9: Yes

Sheet Chart Sample Log
A1: Monthly Chart Sample Log
A2: One row per chart pulled. 10 charts × provider × month. Category mix: 3 DM · 2 CKD · 2 AWV · 2 High-RAF · 1 Random.
A4: Audit Month | B4: Provider ID | C4: Provider Name | D4: Chart # | E4: MRN (masked) | F4: DOS | G4: Category | H4: Payer | I4: Auditor | J4: Status
A5: 2026-07 | B5: FM-001 | C5: Dr. Provider One | D5: 1 | E5: MRN-****-0847 | F5: 2026-06-05 | G5: Diabetes | H5: Medicare Advantage | I5: Auditor A | J5: Pending
A6: 2026-07 | B6: FM-001 | C6: Dr. Provider One | D6: 2 | E6: MRN-****-0912 | F6: 2026-06-08 | G6: Diabetes | H6: Medicare Advantage | I6: Auditor A | J6: Pending
A7: 2026-07 | B7: FM-001 | C7: Dr. Provider One | D7: 3 | E7: MRN-****-1013 | F7: 2026-06-11 | G7: Diabetes | H7: Commercial | I7: Auditor A | J7: Pending
A8: 2026-07 | B8: FM-001 | C8: Dr. Provider One | D8: 4 | E8: MRN-****-1156 | F8: 2026-06-14 | G8: Chronic Kidney Disease | H8: Medicare Advantage | I8: Auditor A | J8: Pending
A9: 2026-07 | B9: FM-001 | C9: Dr. Provider One | D9: 5 | E9: MRN-****-1278 | F9: 2026-06-17 | G9: Chronic Kidney Disease | H9: Medicare Advantage | I9: Auditor A | J9: Pending
A10: 2026-07 | B10: FM-001 | C10: Dr. Provider One | D10: 6 | E10: MRN-****-1301 | F10: 2026-06-19 | G10: Annual Wellness Visit | H10: Medicare Advantage | I10: Auditor A | J10: Pending
A11: 2026-07 | B11: FM-001 | C11: Dr. Provider One | D11: 7 | E11: MRN-****-1355 | F11: 2026-06-22 | G11: Annual Wellness Visit | H11: Medicare Advantage | I11: Auditor A | J11: Pending
A12: 2026-07 | B12: FM-001 | C12: Dr. Provider One | D12: 8 | E12: MRN-****-1402 | F12: 2026-06-24 | G12: High RAF Patient | H12: Medicare Advantage | I12: Auditor A | J12: Pending
A13: 2026-07 | B13: FM-001 | C13: Dr. Provider One | D13: 9 | E13: MRN-****-1476 | F13: 2026-06-26 | G13: High RAF Patient | H13: Medicare Advantage | I13: Auditor A | J13: Pending
A14: 2026-07 | B14: FM-001 | C14: Dr. Provider One | D14: 10 | E14: MRN-****-1523 | F14: 2026-06-28 | G14: Random Selection | H14: Commercial | I14: Auditor A | J14: Pending

Sheet Audit Worksheet
A1: Chart-Level Audit Worksheet
A2: Score each chart on the 5 weighted categories. Column Total auto-computes and Band auto-assigns.
A4: Provider ID | B4: Chart # | C4: MRN (masked) | D4: DOS | E4: Category | F4: Diagnosis Accuracy (0-100) — 30% | G4: Doc Specificity (0-100) — 25% | H4: MEAT Support (0-100) — 25% | I4: HCC Capture (0-100) — 10% | J4: CPT II Reporting (0-100) — 10% | K4: Total Score | L4: Performance Band | M4: Findings / Notes | N4: Requires Re-Audit?
A5: FM-001 | B5: 1 | C5: MRN-****-0847 | D5: 2026-06-05 | E5: Diabetes | K5: =IF(COUNT(F5:J5)<5,"",ROUND(F5*0.30+G5*0.25+H5*0.25+I5*0.10+J5*0.10,1)) | L5: =IF(K5="","",IF(K5>=95,"Excellent",IF(K5>=90,"Meets Expectations",IF(K5>=80,"Needs Improvement","Corrective Education Required")))) | N5: =IF(K5="","",IF(K5<80,"Yes","No"))
A6: FM-001 | B6: 2 | C6: MRN-****-0912 | D6: 2026-06-08 | E6: Diabetes | K6: =IF(COUNT(F6:J6)<5,"",ROUND(F6*0.30+G6*0.25+H6*0.25+I6*0.10+J6*0.10,1)) | L6: =IF(K6="","",IF(K6>=95,"Excellent",IF(K6>=90,"Meets Expectations",IF(K6>=80,"Needs Improvement","Corrective Education Required")))) | N6: =IF(K6="","",IF(K6<80,"Yes","No"))
A7: FM-001 | B7: 3 | C7: MRN-****-1013 | D7: 2026-06-11 | E7: Diabetes | K7: =IF(COUNT(F7:J7)<5,"",ROUND(F7*0.30+G7*0.25+H7*0.25+I7*0.10+J7*0.10,1)) | L7: =IF(K7="","",IF(K7>=95,"Excellent",IF(K7>=90,"Meets Expectations",IF(K7>=80,"Needs Improvement","Corrective Education Required")))) | N7: =IF(K7="","",IF(K7<80,"Yes","No"))
A8: FM-001 | B8: 4 | C8: MRN-****-1156 | D8: 2026-06-14 | E8: Chronic Kidney Disease | K8: =IF(COUNT(F8:J8)<5,"",ROUND(F8*0.30+G8*0.25+H8*0.25+I8*0.10+J8*0.10,1)) | L8: =IF(K8="","",IF(K8>=95,"Excellent",IF(K8>=90,"Meets Expectations",IF(K8>=80,"Needs Improvement","Corrective Education Required")))) | N8: =IF(K8="","",IF(K8<80,"Yes","No"))
A9: FM-001 | B9: 5 | C9: MRN-****-1278 | D9: 2026-06-17 | E9: Chronic Kidney Disease | K9: =IF(COUNT(F9:J9)<5,"",ROUND(F9*0.30+G9*0.25+H9*0.25+I9*0.10+J9*0.10,1)) | L9: =IF(K9="","",IF(K9>=95,"Excellent",IF(K9>=90,"Meets Expectations",IF(K9>=80,"Needs Improvement","Corrective Education Required")))) | N9: =IF(K9="","",IF(K9<80,"Yes","No"))
A10: FM-001 | B10: 6 | C10: MRN-****-1301 | D10: 2026-06-19 | E10: Annual Wellness Visit | K10: =IF(COUNT(F10:J10)<5,"",ROUND(F10*0.30+G10*0.25+H10*0.25+I10*0.10+J10*0.10,1)) | L10: =IF(K10="","",IF(K10>=95,"Excellent",IF(K10>=90,"Meets Expectations",IF(K10>=80,"Needs Improvement","Corrective Education Required")))) | N10: =IF(K10="","",IF(K10<80,"Yes","No"))
A11: FM-001 | B11: 7 | C11: MRN-****-1355 | D11: 2026-06-22 | E11: Annual Wellness Visit | K11: =IF(COUNT(F11:J11)<5,"",ROUND(F11*0.30+G11*0.25+H11*0.25+I11*0.10+J11*0.10,1)) | L11: =IF(K11="","",IF(K11>=95,"Excellent",IF(K11>=90,"Meets Expectations",IF(K11>=80,"Needs Improvement","Corrective Education Required")))) | N11: =IF(K11="","",IF(K11<80,"Yes","No"))
A12: FM-001 | B12: 8 | C12: MRN-****-1402 | D12: 2026-06-24 | E12: High RAF Patient | K12: =IF(COUNT(F12:J12)<5,"",ROUND(F12*0.30+G12*0.25+H12*0.25+I12*0.10+J12*0.10,1)) | L12: =IF(K12="","",IF(K12>=95,"Excellent",IF(K12>=90,"Meets Expectations",IF(K12>=80,"Needs Improvement","Corrective Education Required")))) | N12: =IF(K12="","",IF(K12<80,"Yes","No"))
A13: FM-001 | B13: 9 | C13: MRN-****-1476 | D13: 2026-06-26 | E13: High RAF Patient | K13: =IF(COUNT(F13:J13)<5,"",ROUND(F13*0.30+G13*0.25+H13*0.25+I13*0.10+J13*0.10,1)) | L13: =IF(K13="","",IF(K13>=95,"Excellent",IF(K13>=90,"Meets Expectations",IF(K13>=80,"Needs Improvement","Corrective Education Required")))) | N13: =IF(K13="","",IF(K13<80,"Yes","No"))
A14: FM-001 | B14: 10 | C14: MRN-****-1523 | D14: 2026-06-28 | E14: Random Selection | K14: =IF(COUNT(F14:J14)<5,"",ROUND(F14*0.30+G14*0.25+H14*0.25+I14*0.10+J14*0.10,1)) | L14: =IF(K14="","",IF(K14>=95,"Excellent",IF(K14>=90,"Meets Expectations",IF(K14>=80,"Needs Improvement","Corrective Education Required")))) | N14: =IF(K14="","",IF(K14<80,"Yes","No"))
K15: =IF(COUNT(F15:J15)<5,"",ROUND(F15*0.30+G15*0.25+H15*0.25+I15*0.10+J15*0.10,1)) | L15: =IF(K15="","",IF(K15>=95,"Excellent",IF(K15>=90,"Meets Expectations",IF(K15>=80,"Needs Improvement","Corrective Education Required")))) | N15: =IF(K15="","",IF(K15<80,"Yes","No"))
K16: =IF(COUNT(F16:J16)<5,"",ROUND(F16*0.30+G16*0.25+H16*0.25+I16*0.10+J16*0.10,1)) | L16: =IF(K16="","",IF(K16>=95,"Excellent",IF(K16>=90,"Meets Expectations",IF(K16>=80,"Needs Improvement","Corrective Education Required")))) | N16: =IF(K16="","",IF(K16<80,"Yes","No"))
K17: =IF(COUNT(F17:J17)<5,"",ROUND(F17*0.30+G17*0.25+H17*0.25+I17*0.10+J17*0.10,1)) | L17: =IF(K17="","",IF(K17>=95,"Excellent",IF(K17>=90,"Meets Expectations",IF(K17>=80,"Needs Improvement","Corrective Education Required")))) | N17: =IF(K17="","",IF(K17<80,"Yes","No"))
K18: =IF(COUNT(F18:J18)<5,"",ROUND(F18*0.30+G18*0.25+H18*0.25+I18*0.10+J18*0.10,1)) | L18: =IF(K18="","",IF(K18>=95,"Excellent",IF(K18>=90,"Meets Expectations",IF(K18>=80,"Needs Improvement","Corrective Education Required")))) | N18: =IF(K18="","",IF(K18<80,"Yes","No"))
K19: =IF(COUNT(F19:J19)<5,"",ROUND(F19*0.30+G19*0.25+H19*0.25+I19*0.10+J19*0.10,1)) | L19: =IF(K19="","",IF(K19>=95,"Excellent",IF(K19>=90,"Meets Expectations",IF(K19>=80,"Needs Improvement","Corrective Education Required")))) | N19: =IF(K19="","",IF(K19<80,"Yes","No"))
K20: =IF(COUNT(F20:J20)<5,"",ROUND(F20*0.30+G20*0.25+H20*0.25+I20*0.10+J20*0.10,1)) | L20: =IF(K20="","",IF(K20>=95,"Excellent",IF(K20>=90,"Meets Expectations",IF(K20>=80,"Needs Improvement","Corrective Education Required")))) | N20: =IF(K20="","",IF(K20<80,"Yes","No"))
K21: =IF(COUNT(F21:J21)<5,"",ROUND(F21*0.30+G21*0.25+H21*0.25+I21*0.10+J21*0.10,1)) | L21: =IF(K21="","",IF(K21>=95,"Excellent",IF(K21>=90,"Meets Expectations",IF(K21>=80,"Needs Improvement","Corrective Education Required")))) | N21: =IF(K21="","",IF(K21<80,"Yes","No"))
K22: =IF(COUNT(F22:J22)<5,"",ROUND(F22*0.30+G22*0.25+H22*0.25+I22*0.10+J22*0.10,1)) | L22: =IF(K22="","",IF(K22>=95,"Excellent",IF(K22>=90,"Meets Expectations",IF(K22>=80,"Needs Improvement","Corrective Education Required")))) | N22: =IF(K22="","",IF(K22<80,"Yes","No"))
K23: =IF(COUNT(F23:J23)<5,"",ROUND(F23*0.30+G23*0.25+H23*0.25+I23*0.10+J23*0.10,1)) | L23: =IF(K23="","",IF(K23>=95,"Excellent",IF(K23>=90,"Meets Expectations",IF(K23>=80,"Needs Improvement","Corrective Education Required")))) | N23: =IF(K23="","",IF(K23<80,"Yes","No"))
K24: =IF(COUNT(F24:J24)<5,"",ROUND(F24*0.30+G24*0.25+H24*0.25+I24*0.10+J24*0.10,1)) | L24: =IF(K24="","",IF(K24>=95,"Excellent",IF(K24>=90,"Meets Expectations",IF(K24>=80,"Needs Improvement","Corrective Education Required")))) | N24: =IF(K24="","",IF(K24<80,"Yes","No"))
K25: =IF(COUNT(F25:J25)<5,"",ROUND(F25*0.30+G25*0.25+H25*0.25+I25*0.10+J25*0.10,1)) | L25: =IF(K25="","",IF(K25>=95,"Excellent",IF(K25>=90,"Meets Expectations",IF(K25>=80,"Needs Improvement","Corrective Education Required")))) | N25: =IF(K25="","",IF(K25<80,"Yes","No"))
K26: =IF(COUNT(F26:J26)<5,"",ROUND(F26*0.30+G26*0.25+H26*0.25+I26*0.10+J26*0.10,1)) | L26: =IF(K26="","",IF(K26>=95,"Excellent",IF(K26>=90,"Meets Expectations",IF(K26>=80,"Needs Improvement","Corrective Education Required")))) | N26: =IF(K26="","",IF(K26<80,"Yes","No"))
... K200: =IF(COUNT(F200:J200)<5,"",ROUND(F200*0.30+G200*0.25+H200*0.25+I200*0.10+J200*0.10,1)) | L200: =IF(K200="","",IF(K200>=95,"Excellent",IF(K200>=90,"Meets Expectations",IF(K200>=80,"Needs Improvement","Corrective Education Required")))) | N200: =IF(K200="","",IF(K200<80,"Yes","No"))

Sheet MEAT Checklist
A1: MEAT Validation — Per Diagnosis
A2: One row per chronic diagnosis reported. All four MEAT elements must be documented for a valid capture.
A4: Provider ID | B4: Chart # | C4: ICD-10 Code | D4: Diagnosis Description | E4: Monitor (Y/N) | F4: Evaluate (Y/N) | G4: Assess/Address (Y/N) | H4: Treat (Y/N) | I4: MEAT Score (0-4) | J4: Supported? | K4: Chronic Condition? | L4: Notes
I5: =IF(COUNTIF(E5:H5,"Y")+COUNTIF(E5:H5,"N")=0,"",COUNTIF(E5:H5,"Y")) | J5: =IF(I5="","",IF(I5=4,"Yes","No"))
I6: =IF(COUNTIF(E6:H6,"Y")+COUNTIF(E6:H6,"N")=0,"",COUNTIF(E6:H6,"Y")) | J6: =IF(I6="","",IF(I6=4,"Yes","No"))
I7: =IF(COUNTIF(E7:H7,"Y")+COUNTIF(E7:H7,"N")=0,"",COUNTIF(E7:H7,"Y")) | J7: =IF(I7="","",IF(I7=4,"Yes","No"))
I8: =IF(COUNTIF(E8:H8,"Y")+COUNTIF(E8:H8,"N")=0,"",COUNTIF(E8:H8,"Y")) | J8: =IF(I8="","",IF(I8=4,"Yes","No"))
I9: =IF(COUNTIF(E9:H9,"Y")+COUNTIF(E9:H9,"N")=0,"",COUNTIF(E9:H9,"Y")) | J9: =IF(I9="","",IF(I9=4,"Yes","No"))
I10: =IF(COUNTIF(E10:H10,"Y")+COUNTIF(E10:H10,"N")=0,"",COUNTIF(E10:H10,"Y")) | J10: =IF(I10="","",IF(I10=4,"Yes","No"))
I11: =IF(COUNTIF(E11:H11,"Y")+COUNTIF(E11:H11,"N")=0,"",COUNTIF(E11:H11,"Y")) | J11: =IF(I11="","",IF(I11=4,"Yes","No"))
I12: =IF(COUNTIF(E12:H12,"Y")+COUNTIF(E12:H12,"N")=0,"",COUNTIF(E12:H12,"Y")) | J12: =IF(I12="","",IF(I12=4,"Yes","No"))
I13: =IF(COUNTIF(E13:H13,"Y")+COUNTIF(E13:H13,"N")=0,"",COUNTIF(E13:H13,"Y")) | J13: =IF(I13="","",IF(I13=4,"Yes","No"))
I14: =IF(COUNTIF(E14:H14,"Y")+COUNTIF(E14:H14,"N")=0,"",COUNTIF(E14:H14,"Y")) | J14: =IF(I14="","",IF(I14=4,"Yes","No"))
I15: =IF(COUNTIF(E15:H15,"Y")+COUNTIF(E15:H15,"N")=0,"",COUNTIF(E15:H15,"Y")) | J15: =IF(I15="","",IF(I15=4,"Yes","No"))
I16: =IF(COUNTIF(E16:H16,"Y")+COUNTIF(E16:H16,"N")=0,"",COUNTIF(E16:H16,"Y")) | J16: =IF(I16="","",IF(I16=4,"Yes","No"))
... I200: =IF(COUNTIF(E200:H200,"Y")+COUNTIF(E200:H200,"N")=0,"",COUNTIF(E200:H200,"Y")) | J200: =IF(I200="","",IF(I200=4,"Yes","No"))

Sheet HCC-RAF Tracker
A1: HCC Capture & RAF Impact
A2: Track HCC recaptures, missed opportunities, and RAF delta by chart.
A4: Provider ID | B4: Chart # | C4: Patient Age Band | D4: Payer | E4: Prior-Year HCCs | F4: Recaptured This Year | G4: Suspected Undocumented | H4: New HCCs Captured | I4: Missed HCC Opportunities | J4: Prior RAF | K4: Current RAF | L4: RAF Delta
L5: =IF(AND(J5<>"",K5<>""),ROUND(K5-J5,3),"")
L6: =IF(AND(J6<>"",K6<>""),ROUND(K6-J6,3),"")
L7: =IF(AND(J7<>"",K7<>""),ROUND(K7-J7,3),"")
L8: =IF(AND(J8<>"",K8<>""),ROUND(K8-J8,3),"")
L9: =IF(AND(J9<>"",K9<>""),ROUND(K9-J9,3),"")
L10: =IF(AND(J10<>"",K10<>""),ROUND(K10-J10,3),"")
L11: =IF(AND(J11<>"",K11<>""),ROUND(K11-J11,3),"")
L12: =IF(AND(J12<>"",K12<>""),ROUND(K12-J12,3),"")
L13: =IF(AND(J13<>"",K13<>""),ROUND(K13-J13,3),"")
L14: =IF(AND(J14<>"",K14<>""),ROUND(K14-J14,3),"")
L15: =IF(AND(J15<>"",K15<>""),ROUND(K15-J15,3),"")
L16: =IF(AND(J16<>"",K16<>""),ROUND(K16-J16,3),"")
... L200: =IF(AND(J200<>"",K200<>""),ROUND(K200-J200,3),"")

Sheet CPT II Tracker
A1: CPT II Reporting Compliance
A2: Quality measures — was the CPT II code reported when the measure was in play?
A4: Provider ID | B4: Chart # | C4: Measure | D4: Measure Applicable? (Y/N) | E4: CPT II Reported? (Y/N) | F4: CPT II Code | G4: Reason Code (if not reported) | H4: Gap Identified? | I4: Compliant? | J4: Notes
H5: =IF(OR(D5="",E5=""),"",IF(AND(D5="Y",E5="N"),"Yes","No")) | I5: =IF(OR(D5="",E5=""),"",IF(OR(D5="N",E5="Y"),"Yes","No"))
H6: =IF(OR(D6="",E6=""),"",IF(AND(D6="Y",E6="N"),"Yes","No")) | I6: =IF(OR(D6="",E6=""),"",IF(OR(D6="N",E6="Y"),"Yes","No"))
H7: =IF(OR(D7="",E7=""),"",IF(AND(D7="Y",E7="N"),"Yes","No")) | I7: =IF(OR(D7="",E7=""),"",IF(OR(D7="N",E7="Y"),"Yes","No"))
H8: =IF(OR(D8="",E8=""),"",IF(AND(D8="Y",E8="N"),"Yes","No")) | I8: =IF(OR(D8="",E8=""),"",IF(OR(D8="N",E8="Y"),"Yes","No"))
H9: =IF(OR(D9="",E9=""),"",IF(AND(D9="Y",E9="N"),"Yes","No")) | I9: =IF(OR(D9="",E9=""),"",IF(OR(D9="N",E9="Y"),"Yes","No"))
H10: =IF(OR(D10="",E10=""),"",IF(AND(D10="Y",E10="N"),"Yes","No")) | I10: =IF(OR(D10="",E10=""),"",IF(OR(D10="N",E10="Y"),"Yes","No"))
H11: =IF(OR(D11="",E11=""),"",IF(AND(D11="Y",E11="N"),"Yes","No")) | I11: =IF(OR(D11="",E11=""),"",IF(OR(D11="N",E11="Y"),"Yes","No"))
H12: =IF(OR(D12="",E12=""),"",IF(AND(D12="Y",E12="N"),"Yes","No")) | I12: =IF(OR(D12="",E12=""),"",IF(OR(D12="N",E12="Y"),"Yes","No"))
H13: =IF(OR(D13="",E13=""),"",IF(AND(D13="Y",E13="N"),"Yes","No")) | I13: =IF(OR(D13="",E13=""),"",IF(OR(D13="N",E13="Y"),"Yes","No"))
H14: =IF(OR(D14="",E14=""),"",IF(AND(D14="Y",E14="N"),"Yes","No")) | I14: =IF(OR(D14="",E14=""),"",IF(OR(D14="N",E14="Y"),"Yes","No"))
H15: =IF(OR(D15="",E15=""),"",IF(AND(D15="Y",E15="N"),"Yes","No")) | I15: =IF(OR(D15="",E15=""),"",IF(OR(D15="N",E15="Y"),"Yes","No"))
H16: =IF(OR(D16="",E16=""),"",IF(AND(D16="Y",E16="N"),"Yes","No")) | I16: =IF(OR(D16="",E16=""),"",IF(OR(D16="N",E16="Y"),"Yes","No"))
... H200: =IF(OR(D200="",E200=""),"",IF(AND(D200="Y",E200="N"),"Yes","No")) | I200: =IF(OR(D200="",E200=""),"",IF(OR(D200="N",E200="Y"),"Yes","No"))

Sheet Scorecard
A1: Provider Monthly Scorecard
A2: Auto-rolls up from Audit Worksheet. Score is the average of the provider's 10 chart totals.
A4: Provider ID | B4: Provider Name | C4: Charts Audited | D4: Avg Total Score | E4: Performance Band | F4: # Excellent | G4: # Meets | H4: # Needs Improvement | I4: # Corrective
A5: FM-001 | B5: =IFERROR(VLOOKUP(A5,'Provider Roster'!A5:B30,2,FALSE),"") | C5: =COUNTIFS('Audit Worksheet'!A5:A200,A5,'Audit Worksheet'!K5:K200,"<>") | D5: =IFERROR(ROUND(AVERAGEIFS('Audit Worksheet'!K5:K200,'Audit Worksheet'!A5:A200,A5),1),"") | E5: =IF(D5="","",IF(D5>=95,"Excellent",IF(D5>=90,"Meets Expectations",IF(D5>=80,"Needs Improvement","Corrective Education Required")))) | F5: =COUNTIFS('Audit Worksheet'!A5:A200,A5,'Audit Worksheet'!L5:L200,"Excellent") | G5: =COUNTIFS('Audit Worksheet'!A5:A200,A5,'Audit Worksheet'!L5:L200,"Meets Expectations") | H5: =COUNTIFS('Audit Worksheet'!A5:A200,A5,'Audit Worksheet'!L5:L200,"Needs Improvement") | I5: =COUNTIFS('Audit Worksheet'!A5:A200,A5,'Audit Worksheet'!L5:L200,"Corrective Education Required")
A6: FM-002 | B6: =IFERROR(VLOOKUP(A6,'Provider Roster'!A5:B30,2,FALSE),"") | C6: =COUNTIFS('Audit Worksheet'!A5:A200,A6,'Audit Worksheet'!K5:K200,"<>") | D6: =IFERROR(ROUND(AVERAGEIFS('Audit Worksheet'!K5:K200,'Audit Worksheet'!A5:A200,A6),1),"") | E6: =IF(D6="","",IF(D6>=95,"Excellent",IF(D6>=90,"Meets Expectations",IF(D6>=80,"Needs Improvement","Corrective Education Required")))) | F6: =COUNTIFS('Audit Worksheet'!A5:A200,A6,'Audit Worksheet'!L5:L200,"Excellent") | G6: =COUNTIFS('Audit Worksheet'!A5:A200,A6,'Audit Worksheet'!L5:L200,"Meets Expectations") | H6: =COUNTIFS('Audit Worksheet'!A5:A200,A6,'Audit Worksheet'!L5:L200,"Needs Improvement") | I6: =COUNTIFS('Audit Worksheet'!A5:A200,A6,'Audit Worksheet'!L5:L200,"Corrective Education Required")
A7: IM-001 | B7: =IFERROR(VLOOKUP(A7,'Provider Roster'!A5:B30,2,FALSE),"") | C7: =COUNTIFS('Audit Worksheet'!A5:A200,A7,'Audit Worksheet'!K5:K200,"<>") | D7: =IFERROR(ROUND(AVERAGEIFS('Audit Worksheet'!K5:K200,'Audit Worksheet'!A5:A200,A7),1),"") | E7: =IF(D7="","",IF(D7>=95,"Excellent",IF(D7>=90,"Meets Expectations",IF(D7>=80,"Needs Improvement","Corrective Education Required")))) | F7: =COUNTIFS('Audit Worksheet'!A5:A200,A7,'Audit Worksheet'!L5:L200,"Excellent") | G7: =COUNTIFS('Audit Worksheet'!A5:A200,A7,'Audit Worksheet'!L5:L200,"Meets Expectations") | H7: =COUNTIFS('Audit Worksheet'!A5:A200,A7,'Audit Worksheet'!L5:L200,"Needs Improvement") | I7: =COUNTIFS('Audit Worksheet'!A5:A200,A7,'Audit Worksheet'!L5:L200,"Corrective Education Required")
A8: IM-002 | B8: =IFERROR(VLOOKUP(A8,'Provider Roster'!A5:B30,2,FALSE),"") | C8: =COUNTIFS('Audit Worksheet'!A5:A200,A8,'Audit Worksheet'!K5:K200,"<>") | D8: =IFERROR(ROUND(AVERAGEIFS('Audit Worksheet'!K5:K200,'Audit Worksheet'!A5:A200,A8),1),"") | E8: =IF(D8="","",IF(D8>=95,"Excellent",IF(D8>=90,"Meets Expectations",IF(D8>=80,"Needs Improvement","Corrective Education Required")))) | F8: =COUNTIFS('Audit Worksheet'!A5:A200,A8,'Audit Worksheet'!L5:L200,"Excellent") | G8: =COUNTIFS('Audit Worksheet'!A5:A200,A8,'Audit Worksheet'!L5:L200,"Meets Expectations") | H8: =COUNTIFS('Audit Worksheet'!A5:A200,A8,'Audit Worksheet'!L5:L200,"Needs Improvement") | I8: =COUNTIFS('Audit Worksheet'!A5:A200,A8,'Audit Worksheet'!L5:L200,"Corrective Education Required")
A9: GM-001 | B9: =IFERROR(VLOOKUP(A9,'Provider Roster'!A5:B30,2,FALSE),"") | C9: =COUNTIFS('Audit Worksheet'!A5:A200,A9,'Audit Worksheet'!K5:K200,"<>") | D9: =IFERROR(ROUND(AVERAGEIFS('Audit Worksheet'!K5:K200,'Audit Worksheet'!A5:A200,A9),1),"") | E9: =IF(D9="","",IF(D9>=95,"Excellent",IF(D9>=90,"Meets Expectations",IF(D9>=80,"Needs Improvement","Corrective Education Required")))) | F9: =COUNTIFS('Audit Worksheet'!A5:A200,A9,'Audit Worksheet'!L5:L200,"Excellent") | G9: =COUNTIFS('Audit Worksheet'!A5:A200,A9,'Audit Worksheet'!L5:L200,"Meets Expectations") | H9: =COUNTIFS('Audit Worksheet'!A5:A200,A9,'Audit Worksheet'!L5:L200,"Needs Improvement") | I9: =COUNTIFS('Audit Worksheet'!A5:A200,A9,'Audit Worksheet'!L5:L200,"Corrective Education Required")

Sheet Dashboard
A1: Monthly KPI Dashboard
A2: Cycle-level metrics rolled up from all provider audits.
B4: Metric | C4: Value
B5: Providers audited | C5: =COUNTA('Provider Roster'!A5:A30)-COUNTBLANK('Provider Roster'!A5:A30)
B6: Total charts audited | C6: =COUNTA('Audit Worksheet'!A5:A200)
B7: Charts scored (complete) | C7: =COUNTIF('Audit Worksheet'!K5:K200,">0")
B8: Audit completion rate | C8: =IFERROR(ROUND(COUNTIF('Audit Worksheet'!K5:K200,">0")/COUNTA('Audit Worksheet'!A5:A200),3),"")
B9: Average total score (all charts) | C9: =IFERROR(ROUND(AVERAGE('Audit Worksheet'!K5:K200),1),"")
B10: Charts — Excellent | C10: =COUNTIF('Audit Worksheet'!L5:L200,"Excellent")
B11: Charts — Meets Expectations | C11: =COUNTIF('Audit Worksheet'!L5:L200,"Meets Expectations")
B12: Charts — Needs Improvement | C12: =COUNTIF('Audit Worksheet'!L5:L200,"Needs Improvement")
B13: Charts — Corrective Required | C13: =COUNTIF('Audit Worksheet'!L5:L200,"Corrective Education Required")
B14: Providers below 80% | C14: =COUNTIF(Scorecard!D5:D30,"<80")
B15: Missed HCC opportunities | C15: =SUM('HCC-RAF Tracker'!I5:I200)
B16: New HCCs captured | C16: =SUM('HCC-RAF Tracker'!H5:H200)
B17: Suspected undocumented HCCs | C17: =SUM('HCC-RAF Tracker'!G5:G200)
B18: Avg RAF delta | C18: =IFERROR(ROUND(AVERAGE('HCC-RAF Tracker'!L5:L200),3),"")
B19: CPT II gaps identified | C19: =COUNTIF('CPT II Tracker'!H5:H200,"Yes")
B20: CPT II compliant charts | C20: =COUNTIF('CPT II Tracker'!I5:I200,"Yes")
B21: MEAT-supported diagnoses | C21: =COUNTIF('MEAT Checklist'!J5:J200,"Yes")
B22: MEAT-unsupported diagnoses | C22: =COUNTIF('MEAT Checklist'!J5:J200,"No")
B25: Six-Month Targets
B26: Target | C26: Goal
B27: Reduce unspecified diagnosis usage | C27: -25%
B28: Increase HCC specificity | C28: +20%
B29: Increase CPT II reporting compliance | C29: +15%
B30: Audit completion rate | C30: 100%
B31: Monthly provider education sessions | C31: Delivered
B32: Average provider audit score | C32: >= 90%

Sheet Corrective Action
A1: Corrective Action & Re-Audit Tracker
A2: Providers scoring below 80% or with recurring deficiencies. Re-audit within 60–90 days.
A4: Provider ID | B4: Provider Name | C4: Audit Month | D4: Score | E4: Deficiency Focus | F4: Education Plan | G4: Education Date | H4: Re-Audit Due Date | I4: Re-Audit Score | J4: Status

Sheet Reference
A1: Reference — MEAT · High-Risk Dx · CPT II · Performance Bands
A2: Coding & audit reference used across the workbook.
A4: MEAT Criteria
A5: Element | B5: Meaning | C5: Documentation Example
A6: Monitor | B6: Signs / symptoms / labs monitored | C6: HbA1c 7.8 stable, weight trending down
A7: Evaluate | B7: Response to treatment evaluated | C7: Reviewed BP log — controlled on lisinopril
A8: Assess / Address | B8: Diagnosis reviewed and addressed | C8: DM Type 2 with neuropathy — continues to be a problem
A9: Treat | B9: Treatment plan documented | C9: Continue metformin 1000 mg BID; recheck A1c in 3 mo
A11: High-Risk / High-Impact Diagnoses (audit priority)
A12: ICD-10 | B12: Category | C12: Description | D12: Notes
A13: E11.9 | B13: Diabetes | C13: Type 2 DM without complications | D13: Unspecified — push toward specificity
A14: E11.22 | B14: Diabetes | C14: Type 2 DM with diabetic CKD | D14: HCC combination code
A15: E11.42 | B15: Diabetes | C15: Type 2 DM with polyneuropathy | D15: Common under-reported combo
A16: N18.3 | B16: CKD | C16: Chronic kidney disease, stage 3 (unspecified) | D16: Prefer N18.30 / N18.31 / N18.32
A17: N18.4 | B17: CKD | C17: Chronic kidney disease, stage 4 | D17: HCC
A18: I50.9 | B18: Heart failure | C18: Heart failure, unspecified | D18: Prefer systolic / diastolic + acuity
A19: J44.9 | B19: COPD | C19: COPD, unspecified | D19: Consider J44.1 acute exacerbation
A20: F32.9 | B20: Depression | C20: MDD, single episode, unspecified | D20: Prefer specificity (F32.0–F32.3)
A21: F41.9 | B21: Anxiety | C21: Anxiety disorder, unspecified | D21: Prefer F41.1 GAD when documented
A22: R73.09 | B22: Prediabetes | C22: Abnormal glucose | D22: Missed HCC path — consider E11 criteria
A23: I10 | B23: Hypertension | C23: Essential hypertension | D23: Check for hypertensive HD/CKD combos
A24: Z79.4 | B24: Long-term meds | C24: Long-term insulin use | D24: Required with insulin-dependent DM
A26: CPT II Reporting Priorities
A27: Measure | B27: CPT II Code(s) | C27: Denominator Trigger | D27: Notes
A28: HbA1c <8% | B28: 3044F / 3046F / 3051F / 3052F | C28: Diabetes patients | D28: Report per most recent A1c
A29: BP control <140/90 | B29: 3074F / 3075F / 3077F / 3078F | C29: Hypertension patients | D29: Document both systolic & diastolic
A30: BMI screening & follow-up | B30: G8417 / G8418 / G8420 | C30: All adult visits | D30: Include intervention when abnormal
A31: Tobacco use & cessation | B31: 1036F / 4004F | C31: All adult visits | D31: Screening + counseling combo
A32: Depression screening + plan | B32: G8431 / G8510 | C32: All adult visits | D32: PHQ-2 / PHQ-9 documented
A33: Statin therapy for CVD | B33: 0521F / 4013F | C33: ASCVD / DM / LDL >=190 | D33: On statin, refused, or contraindicated
A34: Diabetic eye exam | B34: 2022F / 2024F / 2026F | C34: Diabetes patients | D34: Negative or positive result
A35: Nephropathy screening | B35: 3060F / 3061F / 3062F | C35: Diabetes patients | D35: Urine albumin / on ACE/ARB
A36: Med rec post-discharge | B36: 1111F | C36: Discharged in last 30 days | D36: Reconciliation documented
A37: Fall risk assessment | B37: 1101F | C37: Age 65+ | D37: Yearly for MA populations
A39: Performance Bands
A40: Score Range | B40: Band | C40: Action
A41: 95 – 100 | B41: Excellent | C41: Positive feedback; use as peer example
A42: 90 – 94 | B42: Meets Expectations | C42: Standard feedback; no action required
A43: 80 – 89 | B43: Needs Improvement | C43: Targeted education; monitor next cycle
A44: < 80 | B44: Corrective Education Required | C44: Structured plan + re-audit within 60–90 days
...
